Workbook

Sheet EQUIPOS VERTICAL
A1: NOMBRE
A2: DT
A3: CAMADA
B4: JUGADOR | C4: PUNTAJE | D4: JUGADOR | E4: PUNTAJE | F4: JUGADOR | G4: PUNTAJE | H4: JUGADOR | I4: PUNTAJE | J4: JUGADOR | K4: PUNTAJE | L4: JUGADOR | M4: PUNTAJE | N4: JUGADOR | O4: PUNTAJE | P4: JUGADOR | Q4: PUNTAJE | R4: JUGADOR | S4: PUNTAJE | T4: JUGADOR | U4: PUNTAJE | V4: JUGADOR | W4: PUNTAJE | X4: JUGADOR | Y4: PUNTAJE | Z4: JUGADOR | AA4: PUNTAJE
A5: Pilar Izquierdo
A6: Hooker
A7: Pilar Derecho
A8: Segunda Línea
A9: Segunda Línea
A10: Ala
A11: Ala
A12: Octavo
A13: Medioscrum
A14: Apertura
A15: Wing Izquierdo
A16: Centro
... A20: Capitán
A21: PUNTAJE TOTAL | B21: =C5+C6+C7+C8+C9+C10+C11+C12+C13+C14+C15+C16+C17+C18+C19+C20 -> 0 | D21: =E5+E6+E7+E8+E9+E10+E11+E12+E13+E14+E15+E16+E17+E18+E19+E20 -> 0 | F21: =G5+G6+G7+G8+G9+G10+G11+G12+G13+G14+G15+G16+G17+G18+G19+G20 -> 0 | H21: =I5+I6+I7+I8+I9+I10+I11+I12+I13+I14+I15+I16+I17+I18+I19+I20 -> 0 | J21: =K5+K6+K7+K8+K9+K10+K11+K12+K13+K14+K15+K16+K17+K18+K19+K20 -> 0 | L21: =M5+M6+M7+M8+M9+M10+M11+M12+M13+M14+M15+M16+M17+M18+M19+M20 -> 0 | N21: =O5+O6+O7+O8+O9+O10+O11+O12+O13+O14+O15+O16+O17+O18+O19+O20 -> 0 | P21: =Q5+Q6+Q7+Q8+Q9+Q10+Q11+Q12+Q13+Q14+Q15+Q16+Q17+Q18+Q19+Q20 -> 0 | R21: =S5+S6+S7+S8+S9+S10+S11+S12+S13+S14+S15+S16+S17+S18+S19+S20 -> 0 | T21: =U5+U6+U7+U8+U9+U10+U11+U12+U13+U14+U15+U16+U17+U18+U19+U20 -> 0 | V21: =W5+W6+W7+W8+W9+W10+W11+W12+W13+W14+W15+W16+W17+W18+W19+W20 -> 0 | X21: =Y5+Y6+Y7+Y8+Y9+Y10+Y11+Y12+Y13+Y14+Y15+Y16+Y17+Y18+Y19+Y20 -> 0 | Z21: =AA5+AA6+AA7+AA8+AA9+AA10+AA11+AA12+AA13+AA14+AA15+AA16+AA17+AA18+AA19+AA20 -> 0

Sheet EQUIPOS HORIZONTAL
A1: NOMBRE | B1: DT | C1: CAMADA | E1: Pilar Izquierdo | F1: Hooker | G1: Pilar Derecho | H1: Segunda Línea | I1: Segunda Línea | J1: Ala | K1: Ala | L1: Octavo | M1: Medioscrum | N1: Apertura | O1: Wing Izquierdo | P1: Centro | Q1: Centro | R1: Wing Derecho | S1: Fullback | T1: Capitán | U1: PUNTAJE TOTAL
A2: GUERRA | B2: JERO FERRARO | C2: 2005 | D2: JUGADOR | E2: =JUGADORES!B204 -> RODRIGUEZ SAULNIER EZEQUIEL | F2: =JUGADORES!B41 -> BRUZZONE VALENTINO | G2: =JUGADORES!B142 -> LUNA IGNACIO | H2: =JUGADORES!B136 -> KUCIC IVAN | I2: =JUGADORES!B237 -> URRUTIA SANTIAGO | J2: =JUGADORES!B63 -> CERVIO SANTINO | K2: =JUGADORES!B102 -> FERRARO JERÓNIMO | L2: =JUGADORES!B199 -> RINGUELET FRANCISCO | U2: =E3+F3+G3+H3+I3+J3+K3+L3+M3+N3+O3+P3+Q3+R3+S3+T3 -> 0
D3: PUNTAJE | E3: =JUGADORES!D204 -> 0 | F3: =JUGADORES!D41 -> 0 | G3: =JUGADORES!D142 -> 0 | H3: =JUGADORES!D136 -> 0 | I3: =JUGADORES!D237 -> 0 | J3: =JUGADORES!D63 -> 0 | K3: =JUGADORES!D102 -> 0 | L3: =JUGADORES!D199 -> 0
A5: Bruzzeles RC | B5: Bruzzo | C5: 2004 | D5: JUGADOR | U5: =E6+F6+G6+H6+I6+J6+K6+L6+M6+N6+O6+P6+Q6+R6+S6+T6 -> 0
D6: PUNTAJE
A8: Siempre kekista nunca verdura. | B8: Juan Pedro bernasconi | C8: 2004 | D8: JUGADOR | U8: =E9+F9+G9+H9+I9+J9+K9+L9+M9+N9+O9+P9+Q9+R9+S9+T9 -> 0
D9: PUNTAJE
A11: YellowStone | B11: Segundo Pineda | C11: 2002 | D11: JUGADOR | U11: =E12+F12+G12+H12+I12+J12+K12+L12+M12+N12+O12+P12+Q12+R12+S12+T12 -> 0
D12: PUNTAJE
A14: #EspecialPantera | B14: Tono | C14: 1998 | D14: JUGADOR | U14: =E15+F15+G15+H15+I15+J15+K15+L15+M15+N15+O15+P15+Q15+R15+S15+T15 -> 0
D15: PUNTAJE
A17: La pochoneta | B17: Pocho | C17: 2001 | D17: JUGADOR | U17: =E18+F18+G18+H18+I18+J18+K18+L18+M18+N18+O18+P18+Q18+R18+S18+T18 -> 0
D18: PUNTAJE
A20: Pana RC | B20: Facundo Panigatti | C20: 2001 | D20: JUGADOR | U20: =E21+F21+G21+H21+I21+J21+K21+L21+M21+N21+O21+P21+Q21+R21+S21+T21 -> 0
D21: PUNTAJE
A23: Piponeta | B23: Bautista erriest | C23: 2000 | D23: JUGADOR | U23: =E24+F24+G24+H24+I24+J24+K24+L24+M24+N24+O24+P24+Q24+R24+S24+T24 -> 0
D24: PUNTAJE
A26: salva fc | B26: salvador rinaldi | C26: 2006 | D26: JUGADOR | U26: =E27+F27+G27+H27+I27+J27+K27+L27+M27+N27+O27+P27+Q27+R27+S27+T27 -> 0
D27: PUNTAJE
A29: LPRC 1994 | B29: Juan Cruz Kaare | C29: 1994 | D29: JUGADOR | U29: =E30+F30+G30+H30+I30+J30+K30+L30+M30+N30+O30+P30+Q30+R30+S30+T30 -> 0
D30: PUNTAJE
A32: Etche10 | B32: Manuel Etcheverry | C32: 2004 | D32: JUGADOR | U32: =E33+F33+G33+H33+I33+J33+K33+L33+M33+N33+O33+P33+Q33+R33+S33+T33 -> 0
D33: PUNTAJE
A35: Coquitos RC | B35: francisco saulnier | C35: 2005 | D35: JUGADOR | U35: =E36+F36+G36+H36+I36+J36+K36+L36+M36+N36+O36+P36+Q36+R36+S36+T36 -> 0
D36: PUNTAJE
A38: Troglioneta | B38: Segundo testa | C38: 2001 | D38: JUGADOR | U38: =E39+F39+G39+H39+I39+J39+K39+L39+M39+N39+O39+P39+Q39+R39+S39+T39 -> 0
D39: PUNTAJE
A41: Peluches xv | B41: Mirko | C41: 2001 | D41: JUGADOR | U41: =E42+F42+G42+H42+I42+J42+K42+L42+M42+N42+O42+P42+Q42+R42+S42+T42 -> 0
D42: PUNTAJE
A44: Revolver rc | B44: Mateo Canosa | C44: 2002 | D44: JUGADOR | U44: =E45+F45+G45+H45+I45+J45+K45+L45+M45+N45+O45+P45+Q45+R45+S45+T45 -> 0
D45: PUNTAJE
A47: Negren rugby club | B47: Mateo Carassale | C47: 2005 | D47: JUGADOR | U47: =E48+F48+G48+H48+I48+J48+K48+L48+M48+N48+O48+P48+Q48+R48+S48+T48 -> 0
D48: PUNTAJE
A50: Chiquitos | B50: Brigo, Valentino | C50: 2005 | D50: JUGADOR | U50: =E51+F51+G51+H51+I51+J51+K51+L51+M51+N51+O51+P51+Q51+R51+S51+T51 -> 0
D51: PUNTAJE
A53: Cartucho XV | B53: Martin Kneiszl | C53: 1996 | D53: JUGADOR | U53: =E54+F54+G54+H54+I54+J54+K54+L54+M54+N54+O54+P54+Q54+R54+S54+T54 -> 0
D54: PUNTAJE
A56: El inframundo | B56: Pulga | C56: 2005 | D56: JUGADOR | U56: =E57+F57+G57+H57+I57+J57+K57+L57+M57+N57+O57+P57+Q57+R57+S57+T57 -> 0
D57: PUNTAJE
A59: La03 | B59: Ventafridda Bautista | C59: 2003 | D59: JUGADOR | U59: =E60+F60+G60+H60+I60+J60+K60+L60+M60+N60+O60+P60+Q60+R60+S60+T60 -> 0
...

Sheet TABLA GENERAL
C3: TABLA GENERAL
C5: EQUIPO | D5: DT | E5: PUNTAJE
B6: 1 | C6: ='EQUIPOS HORIZONTAL'!A2 -> GUERRA | D6: ='EQUIPOS HORIZONTAL'!B2 -> JERO FERRARO | E6: ='EQUIPOS HORIZONTAL'!U2 -> 0
B7: 4 | C7: ='EQUIPOS HORIZONTAL'!A5 -> Bruzzeles RC | D7: ='EQUIPOS HORIZONTAL'!B5 -> Bruzzo | E7: ='EQUIPOS HORIZONTAL'!U5 -> 0
B8: 7 | C8: ='EQUIPOS HORIZONTAL'!A8 -> Siempre kekista nunca verdura. | D8: ='EQUIPOS HORIZONTAL'!B8 -> Juan Pedro bernasconi | E8: ='EQUIPOS HORIZONTAL'!U8 -> 0
B9: 10 | C9: ='EQUIPOS HORIZONTAL'!A11 -> YellowStone | D9: ='EQUIPOS HORIZONTAL'!B11 -> Segundo Pineda | E9: ='EQUIPOS HORIZONTAL'!U11 -> 0
B10: 13 | C10: ='EQUIPOS HORIZONTAL'!A14 -> #EspecialPantera | D10: ='EQUIPOS HORIZONTAL'!B14 -> Tono | E10: ='EQUIPOS HORIZONTAL'!U14 -> 0
B11: 16 | C11: ='EQUIPOS HORIZONTAL'!A17 -> La pochoneta | D11: ='EQUIPOS HORIZONTAL'!B17 -> Pocho | E11: ='EQUIPOS HORIZONTAL'!U17 -> 0
B12: 19 | C12: ='EQUIPOS HORIZONTAL'!A20 -> Pana RC | D12: ='EQUIPOS HORIZONTAL'!B20 -> Facundo Panigatti | E12: ='EQUIPOS HORIZONTAL'!U20 -> 0
B13: 22 | C13: ='EQUIPOS HORIZONTAL'!A23 -> Piponeta | D13: ='EQUIPOS HORIZONTAL'!B23 -> Bautista erriest | E13: ='EQUIPOS HORIZONTAL'!U23 -> 0
B14: 25 | C14: ='EQUIPOS HORIZONTAL'!A26 -> salva fc | D14: ='EQUIPOS HORIZONTAL'!B26 -> salvador rinaldi | E14: ='EQUIPOS HORIZONTAL'!U26 -> 0
B15: 28 | C15: ='EQUIPOS HORIZONTAL'!A29 -> LPRC 1994 | D15: ='EQUIPOS HORIZONTAL'!B29 -> Juan Cruz Kaare | E15: ='EQUIPOS HORIZONTAL'!U29 -> 0
B16: 31 | C16: ='EQUIPOS HORIZONTAL'!A32 -> Etche10 | D16: ='EQUIPOS HORIZONTAL'!B32 -> Manuel Etcheverry | E16: ='EQUIPOS HORIZONTAL'!U32 -> 0
B17: 34 | C17: ='EQUIPOS HORIZONTAL'!A35 -> Coquitos RC | D17: ='EQUIPOS HORIZONTAL'!B35 -> francisco saulnier | E17: ='EQUIPOS HORIZONTAL'!U35 -> 0
B18: 37 | C18: ='EQUIPOS HORIZONTAL'!A38 -> Troglioneta | D18: ='EQUIPOS HORIZONTAL'!B38 -> Segundo testa | E18: ='EQUIPOS HORIZONTAL'!U38 -> 0
B19: 40 | C19: ='EQUIPOS HORIZONTAL'!A41 -> Peluches xv | D19: ='EQUIPOS HORIZONTAL'!B41 -> Mirko | E19: ='EQUIPOS HORIZONTAL'!U41 -> 0
B20: 43 | C20: ='EQUIPOS HORIZONTAL'!A44 -> Revolver rc | D20: ='EQUIPOS HORIZONTAL'!B44 -> Mateo Canosa | E20: ='EQUIPOS HORIZONTAL'!U44 -> 0
B21: 46 | C21: ='EQUIPOS HORIZONTAL'!A47 -> Negren rugby club | D21: ='EQUIPOS HORIZONTAL'!B47 -> Mateo Carassale | E21: ='EQUIPOS HORIZONTAL'!U47 -> 0
B22: 49 | C22: ='EQUIPOS HORIZONTAL'!A50 -> Chiquitos | D22: ='EQUIPOS HORIZONTAL'!B50 -> Brigo, Valentino | E22: ='EQUIPOS HORIZONTAL'!U50 -> 0
B23: 52 | C23: ='EQUIPOS HORIZONTAL'!A53 -> Cartucho XV | D23: ='EQUIPOS HORIZONTAL'!B53 -> Martin Kneiszl | E23: ='EQUIPOS HORIZONTAL'!U53 -> 0
B24: 55 | C24: ='EQUIPOS HORIZONTAL'!A56 -> El inframundo | D24: ='EQUIPOS HORIZONTAL'!B56 -> Pulga | E24: ='EQUIPOS HORIZONTAL'!U56 -> 0
B25: 58 | C25: ='EQUIPOS HORIZONTAL'!A59 -> La03 | D25: ='EQUIPOS HORIZONTAL'!B59 -> Ventafridda Bautista | E25: ='EQUIPOS HORIZONTAL'!U59 -> 0
B26: 61 | C26: ='EQUIPOS HORIZONTAL'!A62 -> Besitos RC | D26: ='EQUIPOS HORIZONTAL'!B62 -> El gordo nawy | E26: ='EQUIPOS HORIZONTAL'!U62 -> 0
B27: 64 | C27: ='EQUIPOS HORIZONTAL'!A65 -> stone rugby cub | D27: ='EQUIPOS HORIZONTAL'!B65 -> roca | E27: ='EQUIPOS HORIZONTAL'!U65 -> 0
B28: 67 | C28: ='EQUIPOS HORIZONTAL'!A68 -> Los guardianes de Gonnet | D28: ='EQUIPOS HORIZONTAL'!B68 -> Facundo Scarpinelli | E28: ='EQUIPOS HORIZONTAL'!U68 -> 0
B29: 70 | C29: ='EQUIPOS HORIZONTAL'!A71 -> Minchard | D29: ='EQUIPOS HORIZONTAL'!B71 -> Franco Giambruni | E29: ='EQUIPOS HORIZONTAL'!U71 -> 0
B30: 73 | C30: ='EQUIPOS HORIZONTAL'!A74 -> Jauretas fc | D30: ='EQUIPOS HORIZONTAL'!B74 -> Jaure | E30: ='EQUIPOS HORIZONTAL'!U74 -> 0
B31: 76 | C31: ='EQUIPOS HORIZONTAL'!A77 -> Topatopa | D31: ='EQUIPOS HORIZONTAL'!B77 -> Giambruni Tomas | E31: ='EQUIPOS HORIZONTAL'!U77 -> 0
B32: 79 | C32: ='EQUIPOS HORIZONTAL'!A80 -> ELPIBEFC | D32: ='EQUIPOS HORIZONTAL'!B80 -> JUAN (el pibe) Soto | E32: ='EQUIPOS HORIZONTAL'!U80 -> 0
B33: 82 | C33: ='EQUIPOS HORIZONTAL'!A83 -> bien igual | D33: ='EQUIPOS HORIZONTAL'!B83 -> Chapa | E33: ='EQUIPOS HORIZONTAL'!U83 -> 0
B34: 85 | C34: ='EQUIPOS HORIZONTAL'!A86 -> La Chona Luna | D34: ='EQUIPOS HORIZONTAL'!B86 -> Iñaki Zuloaga | E34: ='EQUIPOS HORIZONTAL'!U86 -> 0
B35: 88 | C35: ='EQUIPOS HORIZONTAL'!A89 -> Juliano FC. | D35: ='EQUIPOS HORIZONTAL'!B89 -> LUCAJ | E35: ='EQUIPOS HORIZONTAL'!U89 -> 0
B36: 91 | C36: ='EQUIPOS HORIZONTAL'!A92 -> estudio | D36: ='EQUIPOS HORIZONTAL'!B92 -> salvacuruchaga | E36: ='EQUIPOS HORIZONTAL'!U92 -> 0
B37: 94 | C37: ='EQUIPOS HORIZONTAL'!A95 -> Gordo Repulgue Rugby Club | D37: ='EQUIPOS HORIZONTAL'!B95 -> Pedro del Torno | E37: ='EQUIPOS HORIZONTAL'!U95 -> 0
B38: 97 | C38: ='EQUIPOS HORIZONTAL'!A98 -> Team o | D38: ='EQUIPOS HORIZONTAL'!B98 -> Nacho Orlinsky | E38: ='EQUIPOS HORIZONTAL'!U98 -> 0
B39: 100 | C39: ='EQUIPOS HORIZONTAL'!A101 -> Garcios FC | D39: ='EQUIPOS HORIZONTAL'!B101 -> Ivo Neiman | E39: ='EQUIPOS HORIZONTAL'!U101 -> 0
B40: 103 | C40: ='EQUIPOS HORIZONTAL'!A104 -> Los Knock ones de pocho | D40: ='EQUIPOS HORIZONTAL'!B104 -> Antonio Cancela | E40: ='EQUIPOS HORIZONTAL'!U104 -> 0
B41: 106 | C41: ='EQUIPOS HORIZONTAL'!A107 -> Oveneta | D41: ='EQUIPOS HORIZONTAL'!B107 -> Oveja | E41: ='EQUIPOS HORIZONTAL'!U107 -> 0
B42: 109 | C42: ='EQUIPOS HORIZONTAL'!A110 -> Los supendidos RC | D42: ='EQUIPOS HORIZONTAL'!B110 -> HonoLPDG | E42: ='EQUIPOS HORIZONTAL'!U110 -> 0
B43: 112 | C43: ='EQUIPOS HORIZONTAL'!A113 -> Chinola | D43: ='EQUIPOS HORIZONTAL'!B113 -> Marcos alconada | E43: ='EQUIPOS HORIZONTAL'!U113 -> 0
...

Sheet JUGADORES
B2: NOMBRE | C2: POSICIÓN | D2: PUNTAJE TOTAL
B3: ABRIOLA JUAN | C3: TERCERA | D3: ='EVENTOS F1'!L7+'EVENTOS F2'!L7+'EVENTOS F3'!L7+'EVENTOS F4'!L7+'EVENTOS F5'!L7+'EVENTOS F6'!L7+'EVENTOS F7'!L7+'EVENTOS F8'!L7+'EVENTOS F9'!L7+'EVENTOS F10'!L7+'EVENTOS F11'!L7+'EVENTOS F12'!L7+'EVENTOS F13'!L7 -> 0
B4: ADDIECHI FELIPE | C4: FULLBACK | D4: ='EVENTOS F1'!L8+'EVENTOS F2'!L8+'EVENTOS F3'!L8+'EVENTOS F4'!L8+'EVENTOS F5'!L8+'EVENTOS F6'!L8+'EVENTOS F7'!L8+'EVENTOS F8'!L8+'EVENTOS F9'!L8+'EVENTOS F10'!L8+'EVENTOS F11'!L8+'EVENTOS F12'!L8+'EVENTOS F13'!L8 -> 0
B5: ADDIECHI PEDRO | C5: WING | D5: ='EVENTOS F1'!L9+'EVENTOS F2'!L9+'EVENTOS F3'!L9+'EVENTOS F4'!L9+'EVENTOS F5'!L9+'EVENTOS F6'!L9+'EVENTOS F7'!L9+'EVENTOS F8'!L9+'EVENTOS F9'!L9+'EVENTOS F10'!L9+'EVENTOS F11'!L9+'EVENTOS F12'!L9+'EVENTOS F13'!L9 -> 0
B6: AKIMENKO TOMÁS | C6: PILAR | D6: ='EVENTOS F1'!L10+'EVENTOS F2'!L10+'EVENTOS F3'!L10+'EVENTOS F4'!L10+'EVENTOS F5'!L10+'EVENTOS F6'!L10+'EVENTOS F7'!L10+'EVENTOS F8'!L10+'EVENTOS F9'!L10+'EVENTOS F10'!L10+'EVENTOS F11'!L10+'EVENTOS F12'!L10+'EVENTOS F13'!L10 -> 0
B7: ALARCÓN ENZO | C7: WING | D7: ='EVENTOS F1'!L11+'EVENTOS F2'!L11+'EVENTOS F3'!L11+'EVENTOS F4'!L11+'EVENTOS F5'!L11+'EVENTOS F6'!L11+'EVENTOS F7'!L11+'EVENTOS F8'!L11+'EVENTOS F9'!L11+'EVENTOS F10'!L11+'EVENTOS F11'!L11+'EVENTOS F12'!L11+'EVENTOS F13'!L11 -> 0
B8: ALCONADA AGUSTIN | C8: HOOKER | D8: ='EVENTOS F1'!L12+'EVENTOS F2'!L12+'EVENTOS F3'!L12+'EVENTOS F4'!L12+'EVENTOS F5'!L12+'EVENTOS F6'!L12+'EVENTOS F7'!L12+'EVENTOS F8'!L12+'EVENTOS F9'!L12+'EVENTOS F10'!L12+'EVENTOS F11'!L12+'EVENTOS F12'!L12+'EVENTOS F13'!L12 -> 0
B9: ALCONADA MARCOS | C9: CENTRO | D9: ='EVENTOS F1'!L13+'EVENTOS F2'!L13+'EVENTOS F3'!L13+'EVENTOS F4'!L13+'EVENTOS F5'!L13+'EVENTOS F6'!L13+'EVENTOS F7'!L13+'EVENTOS F8'!L13+'EVENTOS F9'!L13+'EVENTOS F10'!L13+'EVENTOS F11'!L13+'EVENTOS F12'!L13+'EVENTOS F13'!L13 -> 0
B10: ALEGRE HOMERO | C10: MEDIOSCRUM | D10: ='EVENTOS F1'!L14+'EVENTOS F2'!L14+'EVENTOS F3'!L14+'EVENTOS F4'!L14+'EVENTOS F5'!L14+'EVENTOS F6'!L14+'EVENTOS F7'!L14+'EVENTOS F8'!L14+'EVENTOS F9'!L14+'EVENTOS F10'!L14+'EVENTOS F11'!L14+'EVENTOS F12'!L14+'EVENTOS F13'!L14 -> 0
B11: ALMERARES GASPAR | C11: CENTRO | D11: ='EVENTOS F1'!L15+'EVENTOS F2'!L15+'EVENTOS F3'!L15+'EVENTOS F4'!L15+'EVENTOS F5'!L15+'EVENTOS F6'!L15+'EVENTOS F7'!L15+'EVENTOS F8'!L15+'EVENTOS F9'!L15+'EVENTOS F10'!L15+'EVENTOS F11'!L15+'EVENTOS F12'!L15+'EVENTOS F13'!L15 -> 0
B12: ALONSO FELIPE | C12: MEDIOSCRUM | D12: ='EVENTOS F1'!L16+'EVENTOS F2'!L16+'EVENTOS F3'!L16+'EVENTOS F4'!L16+'EVENTOS F5'!L16+'EVENTOS F6'!L16+'EVENTOS F7'!L16+'EVENTOS F8'!L16+'EVENTOS F9'!L16+'EVENTOS F10'!L16+'EVENTOS F11'!L16+'EVENTOS F12'!L16+'EVENTOS F13'!L16 -> 0
B13: ALONSO MATÍAS | C13: FULLBACK | D13: ='EVENTOS F1'!L17+'EVENTOS F2'!L17+'EVENTOS F3'!L17+'EVENTOS F4'!L17+'EVENTOS F5'!L17+'EVENTOS F6'!L17+'EVENTOS F7'!L17+'EVENTOS F8'!L17+'EVENTOS F9'!L17+'EVENTOS F10'!L17+'EVENTOS F11'!L17+'EVENTOS F12'!L17+'EVENTOS F13'!L17 -> 0
B14: ALONSO TOMÁS | C14: SEGUNDA | D14: ='EVENTOS F1'!L18+'EVENTOS F2'!L18+'EVENTOS F3'!L18+'EVENTOS F4'!L18+'EVENTOS F5'!L18+'EVENTOS F6'!L18+'EVENTOS F7'!L18+'EVENTOS F8'!L18+'EVENTOS F9'!L18+'EVENTOS F10'!L18+'EVENTOS F11'!L18+'EVENTOS F12'!L18+'EVENTOS F13'!L18 -> 0
... B70: CONTI FERMÍN | C70: PILAR | D70: ='EVENTOS F1'!L74+'EVENTOS F2'!L74+'EVENTOS F3'!L74+'EVENTOS F4'!L74+'EVENTOS F5'!L74+'EVENTOS F6'!L74+'EVENTOS F7'!L74+'EVENTOS F8'!L74+'EVENTOS F9'!L74+'EVENTOS F10'!L74+'EVENTOS F11'!L74+'EVENTOS F12'!L74+'EVENTOS F13'!L74 -> 0
B71: CORONEL JERONIMO | D71: ='EVENTOS F1'!L75+'EVENTOS F2'!L75+'EVENTOS F3'!L75+'EVENTOS F4'!L75+'EVENTOS F5'!L75+'EVENTOS F6'!L75+'EVENTOS F7'!L75+'EVENTOS F8'!L75+'EVENTOS F9'!L75+'EVENTOS F10'!L75+'EVENTOS F11'!L75+'EVENTOS F12'!L75+'EVENTOS F13'!L75 -> 0
B72: COSTE MANUEL | C72: TERCERA | D72: ='EVENTOS F1'!L76+'EVENTOS F2'!L76+'EVENTOS F3'!L76+'EVENTOS F4'!L76+'EVENTOS F5'!L76+'EVENTOS F6'!L76+'EVENTOS F7'!L76+'EVENTOS F8'!L76+'EVENTOS F9'!L76+'EVENTOS F10'!L76+'EVENTOS F11'!L76+'EVENTOS F12'!L76+'EVENTOS F13'!L76 -> 0
B73: CRISPO JUAN IGNACIO | C73: CENTRO | D73: ='EVENTOS F1'!L77+'EVENTOS F2'!L77+'EVENTOS F3'!L77+'EVENTOS F4'!L77+'EVENTOS F5'!L77+'EVENTOS F6'!L77+'EVENTOS F7'!L77+'EVENTOS F8'!L77+'EVENTOS F9'!L77+'EVENTOS F10'!L77+'EVENTOS F11'!L77+'EVENTOS F12'!L77+'EVENTOS F13'!L77 -> 0
B74: CUFRÉ AGUSTIN | C74: TERCERA | D74: ='EVENTOS F1'!L78+'EVENTOS F2'!L78+'EVENTOS F3'!L78+'EVENTOS F4'!L78+'EVENTOS F5'!L78+'EVENTOS F6'!L78+'EVENTOS F7'!L78+'EVENTOS F8'!L78+'EVENTOS F9'!L78+'EVENTOS F10'!L78+'EVENTOS F11'!L78+'EVENTOS F12'!L78+'EVENTOS F13'!L78 -> 0
B75: CUNEO AGUSTIN | C75: TERCERA | D75: ='EVENTOS F1'!L79+'EVENTOS F2'!L79+'EVENTOS F3'!L79+'EVENTOS F4'!L79+'EVENTOS F5'!L79+'EVENTOS F6'!L79+'EVENTOS F7'!L79+'EVENTOS F8'!L79+'EVENTOS F9'!L79+'EVENTOS F10'!L79+'EVENTOS F11'!L79+'EVENTOS F12'!L79+'EVENTOS F13'!L79 -> 0
B76: CUNHA BARAIBAR IÑAKI | C76: CENTRO | D76: ='EVENTOS F1'!L80+'EVENTOS F2'!L80+'EVENTOS F3'!L80+'EVENTOS F4'!L80+'EVENTOS F5'!L80+'EVENTOS F6'!L80+'EVENTOS F7'!L80+'EVENTOS F8'!L80+'EVENTOS F9'!L80+'EVENTOS F10'!L80+'EVENTOS F11'!L80+'EVENTOS F12'!L80+'EVENTOS F13'!L80 -> 0
B77: CURUCHAGA JUAN CRUZ | C77: CENTRO | D77: ='EVENTOS F1'!L81+'EVENTOS F2'!L81+'EVENTOS F3'!L81+'EVENTOS F4'!L81+'EVENTOS F5'!L81+'EVENTOS F6'!L81+'EVENTOS F7'!L81+'EVENTOS F8'!L81+'EVENTOS F9'!L81+'EVENTOS F10'!L81+'EVENTOS F11'!L81+'EVENTOS F12'!L81+'EVENTOS F13'!L81 -> 0
B78: CURUCHAGA SALVADOR | C78: TERCERA | D78: ='EVENTOS F1'!L82+'EVENTOS F2'!L82+'EVENTOS F3'!L82+'EVENTOS F4'!L82+'EVENTOS F5'!L82+'EVENTOS F6'!L82+'EVENTOS F7'!L82+'EVENTOS F8'!L82+'EVENTOS F9'!L82+'EVENTOS F10'!L82+'EVENTOS F11'!L82+'EVENTOS F12'!L82+'EVENTOS F13'!L82 -> 0
B79: D ALESSANDRO FERMIN | C79: APERTURA | D79: ='EVENTOS F1'!L83+'EVENTOS F2'!L83+'EVENTOS F3'!L83+'EVENTOS F4'!L83+'EVENTOS F5'!L83+'EVENTOS F6'!L83+'EVENTOS F7'!L83+'EVENTOS F8'!L83+'EVENTOS F9'!L83+'EVENTOS F10'!L83+'EVENTOS F11'!L83+'EVENTOS F12'!L83+'EVENTOS F13'!L83 -> 0
B80: DAGOSTINO FRANCISCO | C80: MEDIOSCRUM | D80: ='EVENTOS F1'!L84+'EVENTOS F2'!L84+'EVENTOS F3'!L84+'EVENTOS F4'!L84+'EVENTOS F5'!L84+'EVENTOS F6'!L84+'EVENTOS F7'!L84+'EVENTOS F8'!L84+'EVENTOS F9'!L84+'EVENTOS F10'!L84+'EVENTOS F11'!L84+'EVENTOS F12'!L84+'EVENTOS F13'!L84 -> 0
B81: DARODA PEDRO | C81: TERCERA | D81: ='EVENTOS F1'!L85+'EVENTOS F2'!L85+'EVENTOS F3'!L85+'EVENTOS F4'!L85+'EVENTOS F5'!L85+'EVENTOS F6'!L85+'EVENTOS F7'!L85+'EVENTOS F8'!L85+'EVENTOS F9'!L85+'EVENTOS F10'!L85+'EVENTOS F11'!L85+'EVENTOS F12'!L85+'EVENTOS F13'!L85 -> 0
B82: DE LA FUENTE MANUEL | C82: MEDIOSCRUM | D82: ='EVENTOS F1'!L86+'EVENTOS F2'!L86+'EVENTOS F3'!L86+'EVENTOS F4'!L86+'EVENTOS F5'!L86+'EVENTOS F6'!L86+'EVENTOS F7'!L86+'EVENTOS F8'!L86+'EVENTOS F9'!L86+'EVENTOS F10'!L86+'EVENTOS F11'!L86+'EVENTOS F12'!L86+'EVENTOS F13'!L86 -> 0
B83: DE LAZZARI DINO | C83: WING | D83: ='EVENTOS F1'!L87+'EVENTOS F2'!L87+'EVENTOS F3'!L87+'EVENTOS F4'!L87+'EVENTOS F5'!L87+'EVENTOS F6'!L87+'EVENTOS F7'!L87+'EVENTOS F8'!L87+'EVENTOS F9'!L87+'EVENTOS F10'!L87+'EVENTOS F11'!L87+'EVENTOS F12'!L87+'EVENTOS F13'!L87 -> 0
... B85: DEL CERRO ARIEL | C85: PILAR | D85: ='EVENTOS F1'!L89+'EVENTOS F2'!L89+'EVENTOS F3'!L89+'EVENTOS F4'!L89+'EVENTOS F5'!L89+'EVENTOS F6'!L89+'EVENTOS F7'!L89+'EVENTOS F8'!L89+'EVENTOS F9'!L89+'EVENTOS F10'!L89+'EVENTOS F11'!L89+'EVENTOS F12'!L89+'EVENTOS F13'!L89 -> 0
B86: DEL TORNO | C86: TERCERA | D86: ='EVENTOS F1'!L91+'EVENTOS F2'!L90+'EVENTOS F3'!L90+'EVENTOS F4'!L90+'EVENTOS F5'!L90+'EVENTOS F6'!L90+'EVENTOS F7'!L90+'EVENTOS F8'!L90+'EVENTOS F9'!L90+'EVENTOS F10'!L90+'EVENTOS F11'!L90+'EVENTOS F12'!L90+'EVENTOS F13'!L90 -> 0
B87: DEL TUFO FRANCO | C87: MEDIOSCRUM | D87: ='EVENTOS F1'!L92+'EVENTOS F2'!L91+'EVENTOS F3'!L91+'EVENTOS F4'!L91+'EVENTOS F5'!L91+'EVENTOS F6'!L91+'EVENTOS F7'!L91+'EVENTOS F8'!L91+'EVENTOS F9'!L91+'EVENTOS F10'!L91+'EVENTOS F11'!L91+'EVENTOS F12'!L91+'EVENTOS F13'!L91 -> 0
B88: DELUCCHI ENRICO | C88: HOOKER | D88: ='EVENTOS F1'!L93+'EVENTOS F2'!L92+'EVENTOS F3'!L92+'EVENTOS F4'!L92+'EVENTOS F5'!L92+'EVENTOS F6'!L92+'EVENTOS F7'!L92+'EVENTOS F8'!L92+'EVENTOS F9'!L92+'EVENTOS F10'!L92+'EVENTOS F11'!L92+'EVENTOS F12'!L92+'EVENTOS F13'!L92 -> 0
B89: DETTLER GERONIMO | C89: WING | D89: ='EVENTOS F1'!L94+'EVENTOS F2'!L93+'EVENTOS F3'!L93+'EVENTOS F4'!L93+'EVENTOS F5'!L93+'EVENTOS F6'!L93+'EVENTOS F7'!L93+'EVENTOS F8'!L93+'EVENTOS F9'!L93+'EVENTOS F10'!L93+'EVENTOS F11'!L93+'EVENTOS F12'!L93+'EVENTOS F13'!L93 -> 0
B90: DI LUCCA SANTINO | C90: APERTURA | D90: ='EVENTOS F1'!L95+'EVENTOS F2'!L94+'EVENTOS F3'!L94+'EVENTOS F4'!L94+'EVENTOS F5'!L94+'EVENTOS F6'!L94+'EVENTOS F7'!L94+'EVENTOS F8'!L94+'EVENTOS F9'!L94+'EVENTOS F10'!L94+'EVENTOS F11'!L94+'EVENTOS F12'!L94+'EVENTOS F13'!L94 -> 0
B91: DI MARTINO GERONIMO | C91: CENTRO | D91: ='EVENTOS F1'!L96+'EVENTOS F2'!L95+'EVENTOS F3'!L95+'EVENTOS F4'!L95+'EVENTOS F5'!L95+'EVENTOS F6'!L95+'EVENTOS F7'!L95+'EVENTOS F8'!L95+'EVENTOS F9'!L95+'EVENTOS F10'!L95+'EVENTOS F11'!L95+'EVENTOS F12'!L95+'EVENTOS F13'!L95 -> 0
B92: DIAZ CATAN LEANDRO | C92: PILAR | D92: ='EVENTOS F1'!L97+'EVENTOS F2'!L96+'EVENTOS F3'!L96+'EVENTOS F4'!L96+'EVENTOS F5'!L96+'EVENTOS F6'!L96+'EVENTOS F7'!L96+'EVENTOS F8'!L96+'EVENTOS F9'!L96+'EVENTOS F10'!L96+'EVENTOS F11'!L96+'EVENTOS F12'!L96+'EVENTOS F13'!L96 -> 0
B93: DISANTI BAUTISTA | C93: TERCERA | D93: ='EVENTOS F1'!L98+'EVENTOS F2'!L97+'EVENTOS F3'!L97+'EVENTOS F4'!L97+'EVENTOS F5'!L97+'EVENTOS F6'!L97+'EVENTOS F7'!L97+'EVENTOS F8'!L97+'EVENTOS F9'!L97+'EVENTOS F10'!L97+'EVENTOS F11'!L97+'EVENTOS F12'!L97+'EVENTOS F13'!L97 -> 0
B94: ECHEGOYEN THEO | C94: PILAR | D94: ='EVENTOS F1'!L99+'EVENTOS F2'!L98+'EVENTOS F3'!L98+'EVENTOS F4'!L98+'EVENTOS F5'!L98+'EVENTOS F6'!L98+'EVENTOS F7'!L98+'EVENTOS F8'!L98+'EVENTOS F9'!L98+'EVENTOS F10'!L98+'EVENTOS F11'!L98+'EVENTOS F12'!L98+'EVENTOS F13'!L98 -> 0
B95: ERRIEST BAUTISTA | C95: HOOKER | D95: ='EVENTOS F1'!L100+'EVENTOS F2'!L99+'EVENTOS F3'!L99+'EVENTOS F4'!L99+'EVENTOS F5'!L99+'EVENTOS F6'!L99+'EVENTOS F7'!L99+'EVENTOS F8'!L99+'EVENTOS F9'!L99+'EVENTOS F10'!L99+'EVENTOS F11'!L99+'EVENTOS F12'!L99+'EVENTOS F13'!L99 -> 0
B96: ETCHEVERRY MANUEL | C96: APERTURA | D96: ='EVENTOS F1'!L101+'EVENTOS F2'!L100+'EVENTOS F3'!L100+'EVENTOS F4'!L100+'EVENTOS F5'!L100+'EVENTOS F6'!L100+'EVENTOS F7'!L100+'EVENTOS F8'!L100+'EVENTOS F9'!L100+'EVENTOS F10'!L100+'EVENTOS F11'!L100+'EVENTOS F12'!L100+'EVENTOS F13'!L100 -> 0
B97: FEATHERSTON JUAN PEDRO | C97: FULLBACK | D97: ='EVENTOS F1'!L102+'EVENTOS F2'!L101+'EVENTOS F3'!L101+'EVENTOS F4'!L101+'EVENTOS F5'!L101+'EVENTOS F6'!L101+'EVENTOS F7'!L101+'EVENTOS F8'!L101+'EVENTOS F9'!L101+'EVENTOS F10'!L101+'EVENTOS F11'!L101+'EVENTOS F12'!L101+'EVENTOS F13'!L101 -> 0
...

Sheet EVENTOS F1
B4: FECHA 1 | H4: vs ATLETICO ROSARIO | N4: JUGADOR CON MÁS PUNTOS DE LA FECHA | P4: =MAX(L7:L202) -> 0
B6: JUGADOR | C6: POSICIÓN | D6: TITULAR | E6: VICTORIA | F6: TRY | G6: CONVERSIÓN | H6: PENAL | I6: TARJ. AMAR | J6: TARJ. ROJA | K6: DEBUT | L6: PUNTAJE
B7: ABRIOLA JUAN | C7: TERCERA | L7: =((IF(D7="SI",2,0)+(F7*5)+(G7*2)+(H7*3)-((IF(I7="SI",3,0)-((IF(J7="SI",-6,0)+((IF(K7="SI",20,0)))+((IF(E7="SI",1,0))))))))) -> 0
B8: ADDIECHI FELIPE | C8: FULLBACK | L8: =((IF(D8="SI",2,0)+(F8*5)+(G8*2)+(H8*2)-((IF(I8="SI",2,0)-((IF(J8="SI",-5,0)+((IF(K8="SI",10,0))))))))) -> 0 | N8: TITULARIDAD | O8: =+2 -> 2
B9: ADDIECHI PEDRO | C9: WING | L9: =((IF(D9="SI",2,0)+(F9*5)+(G9*2)+(H9*2)-((IF(I9="SI",2,0)-((IF(J9="SI",-5,0)+((IF(K9="SI",10,0))))))))) -> 0 | N9: VICTORIA | O9: 1
B10: AKIMENKO TOMÁS | C10: PILAR | L10: =((IF(D10="SI",2,0)+(F10*5)+(G10*2)+(H10*2)-((IF(I10="SI",2,0)-((IF(J10="SI",-5,0)+((IF(K10="SI",10,0))))))))) -> 0 | N10: TRY | O10: 5
B11: ALARCÓN ENZO | C11: WING | L11: =((IF(D11="SI",2,0)+(F11*5)+(G11*2)+(H11*2)-((IF(I11="SI",2,0)-((IF(J11="SI",-5,0)+((IF(K11="SI",10,0))))))))) -> 0 | N11: CONVERSIÓN | O11: 2
B12: ALCONADA AGUSTIN | C12: HOOKER | L12: =((IF(D12="SI",2,0)+(F12*5)+(G12*2)+(H12*2)-((IF(I12="SI",2,0)-((IF(J12="SI",-5,0)+((IF(K12="SI",10,0))))))))) -> 0 | N12: PENAL | O12: 3
B13: ALCONADA MARCOS | C13: CENTRO | L13: =((IF(D13="SI",2,0)+(F13*5)+(G13*2)+(H13*2)-((IF(I13="SI",2,0)-((IF(J13="SI",-5,0)+((IF(K13="SI",10,0))))))))) -> 0 | N13: TARJ. AMARILLA | O13: -3
B14: ALEGRE HOMERO | C14: MEDIOSCRUM | L14: =((IF(D14="SI",2,0)+(F14*5)+(G14*2)+(H14*2)-((IF(I14="SI",2,0)-((IF(J14="SI",-5,0)+((IF(K14="SI",10,0))))))))) -> 0 | N14: TARJ. ROJA | O14: -6
B15: ALMERARES GASPAR | C15: CENTRO | L15: =((IF(D15="SI",2,0)+(F15*5)+(G15*2)+(H15*2)-((IF(I15="SI",2,0)-((IF(J15="SI",-5,0)+((IF(K15="SI",10,0))))))))) -> 0 | N15: DEBUT | O15: 20
B16: ALONSO FELIPE | C16: MEDIOSCRUM | L16: =((IF(D16="SI",2,0)+(F16*5)+(G16*2)+(H16*2)-((IF(I16="SI",2,0)-((IF(J16="SI",-5,0)+((IF(K16="SI",10,0))))))))) -> 0
B17: ALONSO MATÍAS | C17: FULLBACK | L17: =((IF(D17="SI",2,0)+(F17*5)+(G17*2)+(H17*2)-((IF(I17="SI",2,0)-((IF(J17="SI",-5,0)+((IF(K17="SI",10,0))))))))) -> 0
B18: ALONSO TOMÁS | C18: SEGUNDA | L18: =((IF(D18="SI",2,0)+(F18*5)+(G18*2)+(H18*2)-((IF(I18="SI",2,0)-((IF(J18="SI",-5,0)+((IF(K18="SI",10,0))))))))) -> 0
B19: ALVAREZ HOGGAN RAMIRO | C19: PILAR | L19: =((IF(D19="SI",2,0)+(F19*5)+(G19*2)+(H19*2)-((IF(I19="SI",2,0)-((IF(J19="SI",-5,0)+((IF(K19="SI",10,0))))))))) -> 0
B20: ANNECHINI FELIPE | C20: CENTRO | L20: =((IF(D20="SI",2,0)+(F20*5)+(G20*2)+(H20*2)-((IF(I20="SI",2,0)-((IF(J20="SI",-5,0)+((IF(K20="SI",10,0))))))))) -> 0
B21: ANNECHINI FRANCISCO | C21: FULLBACK | L21: =((IF(D21="SI",2,0)+(F21*5)+(G21*2)+(H21*2)-((IF(I21="SI",2,0)-((IF(J21="SI",-5,0)+((IF(K21="SI",10,0))))))))) -> 0
B22: ANSELMINO FRANCISCO | C22: CENTRO | L22: =((IF(D22="SI",2,0)+(F22*5)+(G22*2)+(H22*2)-((IF(I22="SI",2,0)-((IF(J22="SI",-5,0)+((IF(K22="SI",10,0))))))))) -> 0
B23: ARAUJO DIEGO | C23: WING | L23: =((IF(D23="SI",2,0)+(F23*5)+(G23*2)+(H23*2)-((IF(I23="SI",2,0)-((IF(J23="SI",-5,0)+((IF(K23="SI",10,0))))))))) -> 0
B24: ARMISEN MATEO | C24: PILAR | L24: =((IF(D24="SI",2,0)+(F24*5)+(G24*2)+(H24*2)-((IF(I24="SI",2,0)-((IF(J24="SI",-5,0)+((IF(K24="SI",10,0))))))))) -> 0
B25: ARTECHE MANUEL | C25: WING | L25: =((IF(D25="SI",2,0)+(F25*5)+(G25*2)+(H25*2)-((IF(I25="SI",2,0)-((IF(J25="SI",-5,0)+((IF(K25="SI",10,0))))))))) -> 0
B26: ARTECHE TOMÁS | C26: WING | L26: =((IF(D26="SI",2,0)+(F26*5)+(G26*2)+(H26*2)-((IF(I26="SI",2,0)-((IF(J26="SI",-5,0)+((IF(K26="SI",10,0))))))))) -> 0
B27: BARBOZA TOMÁS | C27: SEGUNDA | L27: =((IF(D27="SI",2,0)+(F27*5)+(G27*2)+(H27*2)-((IF(I27="SI",2,0)-((IF(J27="SI",-5,0)+((IF(K27="SI",10,0))))))))) -> 0
... B74: CONTI FERMÍN | C74: PILAR | L74: =((IF(D74="SI",2,0)+(F74*5)+(G74*2)+(H74*2)-((IF(I74="SI",2,0)-((IF(J74="SI",-5,0)+((IF(K74="SI",10,0))))))))) -> 0
B75: CORONEL JERONIMO | L75: =((IF(D75="SI",2,0)+(F75*5)+(G75*2)+(H75*2)-((IF(I75="SI",2,0)-((IF(J75="SI",-5,0)+((IF(K75="SI",10,0))))))))) -> 0
B76: COSTE MANUEL | C76: TERCERA | L76: =((IF(D76="SI",2,0)+(F76*5)+(G76*2)+(H76*2)-((IF(I76="SI",2,0)-((IF(J76="SI",-5,0)+((IF(K76="SI",10,0))))))))) -> 0
B77: CRISPO JUAN IGNACIO | C77: CENTRO | L77: =((IF(D77="SI",2,0)+(F77*5)+(G77*2)+(H77*2)-((IF(I77="SI",2,0)-((IF(J77="SI",-5,0)+((IF(K77="SI",10,0))))))))) -> 0
B78: CUFRÉ AGUSTIN | C78: TERCERA | L78: =((IF(D78="SI",2,0)+(F78*5)+(G78*2)+(H78*2)-((IF(I78="SI",2,0)-((IF(J78="SI",-5,0)+((IF(K78="SI",10,0))))))))) -> 0
B79: CUNEO AGUSTIN | C79: TERCERA | L79: =((IF(D79="SI",2,0)+(F79*5)+(G79*2)+(H79*2)-((IF(I79="SI",2,0)-((IF(J79="SI",-5,0)+((IF(K79="SI",10,0))))))))) -> 0
B80: CUNHA BARAIBAR IÑAKI | C80: CENTRO | L80: =((IF(D80="SI",2,0)+(F80*5)+(G80*2)+(H80*2)-((IF(I80="SI",2,0)-((IF(J80="SI",-5,0)+((IF(K80="SI",10,0))))))))) -> 0
B81: CURUCHAGA JUAN CRUZ | C81: CENTRO | L81: =((IF(D81="SI",2,0)+(F81*5)+(G81*2)+(H81*2)-((IF(I81="SI",2,0)-((IF(J81="SI",-5,0)+((IF(K81="SI",10,0))))))))) -> 0
B82: CURUCHAGA SALVADOR | C82: TERCERA | L82: =((IF(D82="SI",2,0)+(F82*5)+(G82*2)+(H82*2)-((IF(I82="SI",2,0)-((IF(J82="SI",-5,0)+((IF(K82="SI",10,0))))))))) -> 0
B83: D ALESSANDRO FERMIN | C83: APERTURA | L83: =((IF(D83="SI",2,0)+(F83*5)+(G83*2)+(H83*2)-((IF(I83="SI",2,0)-((IF(J83="SI",-5,0)+((IF(K83="SI",10,0))))))))) -> 0
B84: DAGOSTINO FRANCISCO | C84: MEDIOSCRUM | L84: =((IF(D84="SI",2,0)+(F84*5)+(G84*2)+(H84*2)-((IF(I84="SI",2,0)-((IF(J84="SI",-5,0)+((IF(K84="SI",10,0))))))))) -> 0
B85: DARODA PEDRO | C85: TERCERA | L85: =((IF(D85="SI",2,0)+(F85*5)+(G85*2)+(H85*2)-((IF(I85="SI",2,0)-((IF(J85="SI",-5,0)+((IF(K85="SI",10,0))))))))) -> 0
B86: DE LA FUENTE MANUEL | C86: MEDIOSCRUM | L86: =((IF(D86="SI",2,0)+(F86*5)+(G86*2)+(H86*2)-((IF(I86="SI",2,0)-((IF(J86="SI",-5,0)+((IF(K86="SI",10,0))))))))) -> 0
B87: DE LAZZARI DINO | C87: WING | L87: =((IF(D87="SI",2,0)+(F87*5)+(G87*2)+(H87*2)-((IF(I87="SI",2,0)-((IF(J87="SI",-5,0)+((IF(K87="SI",10,0))))))))) -> 0
... B250: ZULOAGA IÑAKI | C250: TERCERA | L250: =((IF(D250="SI",2,0)+(F250*5)+(G250*2)+(H250*2)-((IF(I250="SI",2,0)-((IF(J250="SI",-5,0)+((IF(K250="SI",10,0))))))))) -> 0

Sheet EVENTOS F2
B4: FECHA 2 | H4: vs LOS TILOS | N4: JUGADOR CON MÁS PUNTOS DE LA FECHA | P4: =MAX(L7:L198) -> 0
B6: JUGADOR | C6: POSICIÓN | D6: TITULAR | E6: VICTORIA | F6: TRY | G6: CONVERSIÓN | H6: PENAL | I6: TARJ. AMAR | J6: TARJ. ROJA | K6: DEBUT | L6: PUNTAJE
B7: ABRIOLA JUAN | C7: TERCERA | L7: =((IF(D7="SI",2,0)+(F7*5)+(G7*2)+(H7*3)-((IF(I7="SI",3,0)-((IF(J7="SI",-6,0)+((IF(K7="SI",20,0)))+((IF(E7="SI",1,0))))))))) -> 0
B8: ADDIECHI FELIPE | C8: FULLBACK | L8: =((IF(D8="SI",2,0)+(F8*5)+(G8*2)+(H8*2)-((IF(I8="SI",2,0)-((IF(J8="SI",-5,0)+((IF(K8="SI",10,0))))))))) -> 0 | N8: TITULARIDAD | O8: =+2 -> 2
B9: ADDIECHI PEDRO | C9: WING | L9: =((IF(D9="SI",2,0)+(F9*5)+(G9*2)+(H9*2)-((IF(I9="SI",2,0)-((IF(J9="SI",-5,0)+((IF(K9="SI",10,0))))))))) -> 0 | N9: VICTORIA | O9: 1
B10: AKIMENKO TOMÁS | C10: PILAR | L10: =((IF(D10="SI",2,0)+(F10*5)+(G10*2)+(H10*2)-((IF(I10="SI",2,0)-((IF(J10="SI",-5,0)+((IF(K10="SI",10,0))))))))) -> 0 | N10: TRY | O10: 5
B11: ALARCÓN ENZO | C11: WING | L11: =((IF(D11="SI",2,0)+(F11*5)+(G11*2)+(H11*2)-((IF(I11="SI",2,0)-((IF(J11="SI",-5,0)+((IF(K11="SI",10,0))))))))) -> 0 | N11: CONVERSIÓN | O11: 2
B12: ALCONADA AGUSTIN | C12: HOOKER | L12: =((IF(D12="SI",2,0)+(F12*5)+(G12*2)+(H12*2)-((IF(I12="SI",2,0)-((IF(J12="SI",-5,0)+((IF(K12="SI",10,0))))))))) -> 0 | N12: PENAL | O12: 3
B13: ALCONADA MARCOS | C13: CENTRO | L13: =((IF(D13="SI",2,0)+(F13*5)+(G13*2)+(H13*2)-((IF(I13="SI",2,0)-((IF(J13="SI",-5,0)+((IF(K13="SI",10,0))))))))) -> 0 | N13: TARJ. AMARILLA | O13: -3
B14: ALEGRE HOMERO | C14: MEDIOSCRUM | L14: =((IF(D14="SI",2,0)+(F14*5)+(G14*2)+(H14*2)-((IF(I14="SI",2,0)-((IF(J14="SI",-5,0)+((IF(K14="SI",10,0))))))))) -> 0 | N14: TARJ. ROJA | O14: -6
B15: ALMERARES GASPAR | C15: CENTRO | L15: =((IF(D15="SI",2,0)+(F15*5)+(G15*2)+(H15*2)-((IF(I15="SI",2,0)-((IF(J15="SI",-5,0)+((IF(K15="SI",10,0))))))))) -> 0 | N15: DEBUT | O15: 20
B16: ALONSO FELIPE | C16: MEDIOSCRUM | L16: =((IF(D16="SI",2,0)+(F16*5)+(G16*2)+(H16*2)-((IF(I16="SI",2,0)-((IF(J16="SI",-5,0)+((IF(K16="SI",10,0))))))))) -> 0
B17: ALONSO MATÍAS | C17: FULLBACK | L17: =((IF(D17="SI",2,0)+(F17*5)+(G17*2)+(H17*2)-((IF(I17="SI",2,0)-((IF(J17="SI",-5,0)+((IF(K17="SI",10,0))))))))) -> 0
B18: ALONSO TOMÁS | C18: SEGUNDA | L18: =((IF(D18="SI",2,0)+(F18*5)+(G18*2)+(H18*2)-((IF(I18="SI",2,0)-((IF(J18="SI",-5,0)+((IF(K18="SI",10,0))))))))) -> 0
B19: ALVAREZ HOGGAN RAMIRO | C19: PILAR | L19: =((IF(D19="SI",2,0)+(F19*5)+(G19*2)+(H19*2)-((IF(I19="SI",2,0)-((IF(J19="SI",-5,0)+((IF(K19="SI",10,0))))))))) -> 0
B20: ANNECHINI FELIPE | C20: CENTRO | L20: =((IF(D20="SI",2,0)+(F20*5)+(G20*2)+(H20*2)-((IF(I20="SI",2,0)-((IF(J20="SI",-5,0)+((IF(K20="SI",10,0))))))))) -> 0
B21: ANNECHINI FRANCISCO | C21: FULLBACK | L21: =((IF(D21="SI",2,0)+(F21*5)+(G21*2)+(H21*2)-((IF(I21="SI",2,0)-((IF(J21="SI",-5,0)+((IF(K21="SI",10,0))))))))) -> 0
B22: ANSELMINO FRANCISCO | C22: CENTRO | L22: =((IF(D22="SI",2,0)+(F22*5)+(G22*2)+(H22*2)-((IF(I22="SI",2,0)-((IF(J22="SI",-5,0)+((IF(K22="SI",10,0))))))))) -> 0
B23: ARAUJO DIEGO | C23: WING | L23: =((IF(D23="SI",2,0)+(F23*5)+(G23*2)+(H23*2)-((IF(I23="SI",2,0)-((IF(J23="SI",-5,0)+((IF(K23="SI",10,0))))))))) -> 0
B24: ARMISEN MATEO | C24: PILAR | L24: =((IF(D24="SI",2,0)+(F24*5)+(G24*2)+(H24*2)-((IF(I24="SI",2,0)-((IF(J24="SI",-5,0)+((IF(K24="SI",10,0))))))))) -> 0
B25: ARTECHE MANUEL | C25: WING | L25: =((IF(D25="SI",2,0)+(F25*5)+(G25*2)+(H25*2)-((IF(I25="SI",2,0)-((IF(J25="SI",-5,0)+((IF(K25="SI",10,0))))))))) -> 0
B26: ARTECHE TOMÁS | C26: WING | L26: =((IF(D26="SI",2,0)+(F26*5)+(G26*2)+(H26*2)-((IF(I26="SI",2,0)-((IF(J26="SI",-5,0)+((IF(K26="SI",10,0))))))))) -> 0
B27: BARBOZA TOMÁS | C27: SEGUNDA | L27: =((IF(D27="SI",2,0)+(F27*5)+(G27*2)+(H27*2)-((IF(I27="SI",2,0)-((IF(J27="SI",-5,0)+((IF(K27="SI",10,0))))))))) -> 0
... B74: CONTI FERMÍN | C74: PILAR | L74: =((IF(D74="SI",2,0)+(F74*5)+(G74*2)+(H74*2)-((IF(I74="SI",2,0)-((IF(J74="SI",-5,0)+((IF(K74="SI",10,0))))))))) -> 0
B75: CORONEL JERONIMO | L75: =((IF(D75="SI",2,0)+(F75*5)+(G75*2)+(H75*2)-((IF(I75="SI",2,0)-((IF(J75="SI",-5,0)+((IF(K75="SI",10,0))))))))) -> 0
B76: COSTE MANUEL | C76: TERCERA | L76: =((IF(D76="SI",2,0)+(F76*5)+(G76*2)+(H76*2)-((IF(I76="SI",2,0)-((IF(J76="SI",-5,0)+((IF(K76="SI",10,0))))))))) -> 0
B77: CRISPO JUAN IGNACIO | C77: CENTRO | L77: =((IF(D77="SI",2,0)+(F77*5)+(G77*2)+(H77*2)-((IF(I77="SI",2,0)-((IF(J77="SI",-5,0)+((IF(K77="SI",10,0))))))))) -> 0
B78: CUFRÉ AGUSTIN | C78: TERCERA | L78: =((IF(D78="SI",2,0)+(F78*5)+(G78*2)+(H78*2)-((IF(I78="SI",2,0)-((IF(J78="SI",-5,0)+((IF(K78="SI",10,0))))))))) -> 0
B79: CUNEO AGUSTIN | C79: TERCERA | L79: =((IF(D79="SI",2,0)+(F79*5)+(G79*2)+(H79*2)-((IF(I79="SI",2,0)-((IF(J79="SI",-5,0)+((IF(K79="SI",10,0))))))))) -> 0
B80: CUNHA BARAIBAR IÑAKI | C80: CENTRO | L80: =((IF(D80="SI",2,0)+(F80*5)+(G80*2)+(H80*2)-((IF(I80="SI",2,0)-((IF(J80="SI",-5,0)+((IF(K80="SI",10,0))))))))) -> 0
B81: CURUCHAGA JUAN CRUZ | C81: CENTRO | L81: =((IF(D81="SI",2,0)+(F81*5)+(G81*2)+(H81*2)-((IF(I81="SI",2,0)-((IF(J81="SI",-5,0)+((IF(K81="SI",10,0))))))))) -> 0
B82: CURUCHAGA SALVADOR | C82: TERCERA | L82: =((IF(D82="SI",2,0)+(F82*5)+(G82*2)+(H82*2)-((IF(I82="SI",2,0)-((IF(J82="SI",-5,0)+((IF(K82="SI",10,0))))))))) -> 0
B83: D ALESSANDRO FERMIN | C83: APERTURA | L83: =((IF(D83="SI",2,0)+(F83*5)+(G83*2)+(H83*2)-((IF(I83="SI",2,0)-((IF(J83="SI",-5,0)+((IF(K83="SI",10,0))))))))) -> 0
B84: DAGOSTINO FRANCISCO | C84: MEDIOSCRUM | L84: =((IF(D84="SI",2,0)+(F84*5)+(G84*2)+(H84*2)-((IF(I84="SI",2,0)-((IF(J84="SI",-5,0)+((IF(K84="SI",10,0))))))))) -> 0
B85: DARODA PEDRO | C85: TERCERA | L85: =((IF(D85="SI",2,0)+(F85*5)+(G85*2)+(H85*2)-((IF(I85="SI",2,0)-((IF(J85="SI",-5,0)+((IF(K85="SI",10,0))))))))) -> 0
B86: DE LA FUENTE MANUEL | C86: MEDIOSCRUM | L86: =((IF(D86="SI",2,0)+(F86*5)+(G86*2)+(H86*2)-((IF(I86="SI",2,0)-((IF(J86="SI",-5,0)+((IF(K86="SI",10,0))))))))) -> 0
B87: DE LAZZARI DINO | C87: WING | L87: =((IF(D87="SI",2,0)+(F87*5)+(G87*2)+(H87*2)-((IF(I87="SI",2,0)-((IF(J87="SI",-5,0)+((IF(K87="SI",10,0))))))))) -> 0
... B246: SAULNIER FRANCISCO | C246: MEDIOSCRUM | L246: =((IF(D246="SI",2,0)+(F246*5)+(G246*2)+(H246*2)-((IF(I246="SI",2,0)-((IF(J246="SI",-5,0)+((IF(K246="SI",10,0))))))))) -> 0

Sheet EVENTOS F3
B4: FECHA 3 | H4: vs CASI | N4: JUGADOR CON MÁS PUNTOS DE LA FECHA | P4: =MAX(L7:L198) -> 0
B6: JUGADOR | C6: POSICIÓN | D6: TITULAR | E6: VICTORIA | F6: TRY | G6: CONVERSIÓN | H6: PENAL | I6: TARJ. AMAR | J6: TARJ. ROJA | K6: DEBUT | L6: PUNTAJE
B7: ABRIOLA JUAN | C7: TERCERA | L7: =((IF(D7="SI",2,0)+(F7*5)+(G7*2)+(H7*3)-((IF(I7="SI",3,0)-((IF(J7="SI",-6,0)+((IF(K7="SI",20,0)))+((IF(E7="SI",1,0))))))))) -> 0
B8: ADDIECHI FELIPE | C8: FULLBACK | L8: =((IF(D8="SI",2,0)+(F8*5)+(G8*2)+(H8*2)-((IF(I8="SI",2,0)-((IF(J8="SI",-5,0)+((IF(K8="SI",10,0))))))))) -> 0 | N8: TITULARIDAD | O8: =+2 -> 2
B9: ADDIECHI PEDRO | C9: WING | L9: =((IF(D9="SI",2,0)+(F9*5)+(G9*2)+(H9*2)-((IF(I9="SI",2,0)-((IF(J9="SI",-5,0)+((IF(K9="SI",10,0))))))))) -> 0 | N9: VICTORIA | O9: 1
B10: AKIMENKO TOMÁS | C10: PILAR | L10: =((IF(D10="SI",2,0)+(F10*5)+(G10*2)+(H10*2)-((IF(I10="SI",2,0)-((IF(J10="SI",-5,0)+((IF(K10="SI",10,0))))))))) -> 0 | N10: TRY | O10: 5
B11: ALARCÓN ENZO | C11: WING | L11: =((IF(D11="SI",2,0)+(F11*5)+(G11*2)+(H11*2)-((IF(I11="SI",2,0)-((IF(J11="SI",-5,0)+((IF(K11="SI",10,0))))))))) -> 0 | N11: CONVERSIÓN | O11: 2
B12: ALCONADA AGUSTIN | C12: HOOKER | L12: =((IF(D12="SI",2,0)+(F12*5)+(G12*2)+(H12*2)-((IF(I12="SI",2,0)-((IF(J12="SI",-5,0)+((IF(K12="SI",10,0))))))))) -> 0 | N12: PENAL | O12: 3
B13: ALCONADA MARCOS | C13: CENTRO | L13: =((IF(D13="SI",2,0)+(F13*5)+(G13*2)+(H13*2)-((IF(I13="SI",2,0)-((IF(J13="SI",-5,0)+((IF(K13="SI",10,0))))))))) -> 0 | N13: TARJ. AMARILLA | O13: -3
B14: ALEGRE HOMERO | C14: MEDIOSCRUM | L14: =((IF(D14="SI",2,0)+(F14*5)+(G14*2)+(H14*2)-((IF(I14="SI",2,0)-((IF(J14="SI",-5,0)+((IF(K14="SI",10,0))))))))) -> 0 | N14: TARJ. ROJA | O14: -6
B15: ALMERARES GASPAR | C15: CENTRO | L15: =((IF(D15="SI",2,0)+(F15*5)+(G15*2)+(H15*2)-((IF(I15="SI",2,0)-((IF(J15="SI",-5,0)+((IF(K15="SI",10,0))))))))) -> 0 | N15: DEBUT | O15: 20
B16: ALONSO FELIPE | C16: MEDIOSCRUM | L16: =((IF(D16="SI",2,0)+(F16*5)+(G16*2)+(H16*2)-((IF(I16="SI",2,0)-((IF(J16="SI",-5,0)+((IF(K16="SI",10,0))))))))) -> 0
B17: ALONSO MATÍAS | C17: FULLBACK | L17: =((IF(D17="SI",2,0)+(F17*5)+(G17*2)+(H17*2)-((IF(I17="SI",2,0)-((IF(J17="SI",-5,0)+((IF(K17="SI",10,0))))))))) -> 0
B18: ALONSO TOMÁS | C18: SEGUNDA | L18: =((IF(D18="SI",2,0)+(F18*5)+(G18*2)+(H18*2)-((IF(I18="SI",2,0)-((IF(J18="SI",-5,0)+((IF(K18="SI",10,0))))))))) -> 0
B19: ALVAREZ HOGGAN RAMIRO | C19: PILAR | L19: =((IF(D19="SI",2,0)+(F19*5)+(G19*2)+(H19*2)-((IF(I19="SI",2,0)-((IF(J19="SI",-5,0)+((IF(K19="SI",10,0))))))))) -> 0
B20: ANNECHINI FELIPE | C20: CENTRO | L20: =((IF(D20="SI",2,0)+(F20*5)+(G20*2)+(H20*2)-((IF(I20="SI",2,0)-((IF(J20="SI",-5,0)+((IF(K20="SI",10,0))))))))) -> 0
B21: ANNECHINI FRANCISCO | C21: FULLBACK | L21: =((IF(D21="SI",2,0)+(F21*5)+(G21*2)+(H21*2)-((IF(I21="SI",2,0)-((IF(J21="SI",-5,0)+((IF(K21="SI",10,0))))))))) -> 0
B22: ANSELMINO FRANCISCO | C22: CENTRO | L22: =((IF(D22="SI",2,0)+(F22*5)+(G22*2)+(H22*2)-((IF(I22="SI",2,0)-((IF(J22="SI",-5,0)+((IF(K22="SI",10,0))))))))) -> 0
B23: ARAUJO DIEGO | C23: WING | L23: =((IF(D23="SI",2,0)+(F23*5)+(G23*2)+(H23*2)-((IF(I23="SI",2,0)-((IF(J23="SI",-5,0)+((IF(K23="SI",10,0))))))))) -> 0
B24: ARMISEN MATEO | C24: PILAR | L24: =((IF(D24="SI",2,0)+(F24*5)+(G24*2)+(H24*2)-((IF(I24="SI",2,0)-((IF(J24="SI",-5,0)+((IF(K24="SI",10,0))))))))) -> 0
B25: ARTECHE MANUEL | C25: WING | L25: =((IF(D25="SI",2,0)+(F25*5)+(G25*2)+(H25*2)-((IF(I25="SI",2,0)-((IF(J25="SI",-5,0)+((IF(K25="SI",10,0))))))))) -> 0
B26: ARTECHE TOMÁS | C26: WING | L26: =((IF(D26="SI",2,0)+(F26*5)+(G26*2)+(H26*2)-((IF(I26="SI",2,0)-((IF(J26="SI",-5,0)+((IF(K26="SI",10,0))))))))) -> 0
B27: BARBOZA TOMÁS | C27: SEGUNDA | L27: =((IF(D27="SI",2,0)+(F27*5)+(G27*2)+(H27*2)-((IF(I27="SI",2,0)-((IF(J27="SI",-5,0)+((IF(K27="SI",10,0))))))))) -> 0
... B74: CONTI FERMÍN | C74: PILAR | L74: =((IF(D74="SI",2,0)+(F74*5)+(G74*2)+(H74*2)-((IF(I74="SI",2,0)-((IF(J74="SI",-5,0)+((IF(K74="SI",10,0))))))))) -> 0
B75: CORONEL JERONIMO | L75: =((IF(D75="SI",2,0)+(F75*5)+(G75*2)+(H75*2)-((IF(I75="SI",2,0)-((IF(J75="SI",-5,0)+((IF(K75="SI",10,0))))))))) -> 0
B76: COSTE MANUEL | C76: TERCERA | L76: =((IF(D76="SI",2,0)+(F76*5)+(G76*2)+(H76*2)-((IF(I76="SI",2,0)-((IF(J76="SI",-5,0)+((IF(K76="SI",10,0))))))))) -> 0
B77: CRISPO JUAN IGNACIO | C77: CENTRO | L77: =((IF(D77="SI",2,0)+(F77*5)+(G77*2)+(H77*2)-((IF(I77="SI",2,0)-((IF(J77="SI",-5,0)+((IF(K77="SI",10,0))))))))) -> 0
B78: CUFRÉ AGUSTIN | C78: TERCERA | L78: =((IF(D78="SI",2,0)+(F78*5)+(G78*2)+(H78*2)-((IF(I78="SI",2,0)-((IF(J78="SI",-5,0)+((IF(K78="SI",10,0))))))))) -> 0
B79: CUNEO AGUSTIN | C79: TERCERA | L79: =((IF(D79="SI",2,0)+(F79*5)+(G79*2)+(H79*2)-((IF(I79="SI",2,0)-((IF(J79="SI",-5,0)+((IF(K79="SI",10,0))))))))) -> 0
B80: CUNHA BARAIBAR IÑAKI | C80: CENTRO | L80: =((IF(D80="SI",2,0)+(F80*5)+(G80*2)+(H80*2)-((IF(I80="SI",2,0)-((IF(J80="SI",-5,0)+((IF(K80="SI",10,0))))))))) -> 0
B81: CURUCHAGA JUAN CRUZ | C81: CENTRO | L81: =((IF(D81="SI",2,0)+(F81*5)+(G81*2)+(H81*2)-((IF(I81="SI",2,0)-((IF(J81="SI",-5,0)+((IF(K81="SI",10,0))))))))) -> 0
B82: CURUCHAGA SALVADOR | C82: TERCERA | L82: =((IF(D82="SI",2,0)+(F82*5)+(G82*2)+(H82*2)-((IF(I82="SI",2,0)-((IF(J82="SI",-5,0)+((IF(K82="SI",10,0))))))))) -> 0
B83: D ALESSANDRO FERMIN | C83: APERTURA | L83: =((IF(D83="SI",2,0)+(F83*5)+(G83*2)+(H83*2)-((IF(I83="SI",2,0)-((IF(J83="SI",-5,0)+((IF(K83="SI",10,0))))))))) -> 0
B84: DAGOSTINO FRANCISCO | C84: MEDIOSCRUM | L84: =((IF(D84="SI",2,0)+(F84*5)+(G84*2)+(H84*2)-((IF(I84="SI",2,0)-((IF(J84="SI",-5,0)+((IF(K84="SI",10,0))))))))) -> 0
B85: DARODA PEDRO | C85: TERCERA | L85: =((IF(D85="SI",2,0)+(F85*5)+(G85*2)+(H85*2)-((IF(I85="SI",2,0)-((IF(J85="SI",-5,0)+((IF(K85="SI",10,0))))))))) -> 0
B86: DE LA FUENTE MANUEL | C86: MEDIOSCRUM | L86: =((IF(D86="SI",2,0)+(F86*5)+(G86*2)+(H86*2)-((IF(I86="SI",2,0)-((IF(J86="SI",-5,0)+((IF(K86="SI",10,0))))))))) -> 0
B87: DE LAZZARI DINO | C87: WING | L87: =((IF(D87="SI",2,0)+(F87*5)+(G87*2)+(H87*2)-((IF(I87="SI",2,0)-((IF(J87="SI",-5,0)+((IF(K87="SI",10,0))))))))) -> 0
... B246: SAULNIER FRANCISCO | C246: MEDIOSCRUM | L246: =((IF(D246="SI",2,0)+(F246*5)+(G246*2)+(H246*2)-((IF(I246="SI",2,0)-((IF(J246="SI",-5,0)+((IF(K246="SI",10,0))))))))) -> 0

Sheet EVENTOS F4
B4: FECHA 4 | H4: vs CUBA | N4: JUGADOR CON MÁS PUNTOS DE LA FECHA | P4: =MAX(L7:L198) -> 0
B6: JUGADOR | C6: POSICIÓN | D6: TITULAR | E6: VICTORIA | F6: TRY | G6: CONVERSIÓN | H6: PENAL | I6: TARJ. AMAR | J6: TARJ. ROJA | K6: DEBUT | L6: PUNTAJE
B7: ABRIOLA JUAN | C7: TERCERA | L7: =((IF(D7="SI",2,0)+(F7*5)+(G7*2)+(H7*3)-((IF(I7="SI",3,0)-((IF(J7="SI",-6,0)+((IF(K7="SI",20,0)))+((IF(E7="SI",1,0))))))))) -> 0
B8: ADDIECHI FELIPE | C8: FULLBACK | L8: =((IF(D8="SI",2,0)+(F8*5)+(G8*2)+(H8*2)-((IF(I8="SI",2,0)-((IF(J8="SI",-5,0)+((IF(K8="SI",10,0))))))))) -> 0 | N8: TITULARIDAD | O8: =+2 -> 2
B9: ADDIECHI PEDRO | C9: WING | L9: =((IF(D9="SI",2,0)+(F9*5)+(G9*2)+(H9*2)-((IF(I9="SI",2,0)-((IF(J9="SI",-5,0)+((IF(K9="SI",10,0))))))))) -> 0 | N9: VICTORIA | O9: 1
B10: AKIMENKO TOMÁS | C10: PILAR | L10: =((IF(D10="SI",2,0)+(F10*5)+(G10*2)+(H10*2)-((IF(I10="SI",2,0)-((IF(J10="SI",-5,0)+((IF(K10="SI",10,0))))))))) -> 0 | N10: TRY | O10: 5
B11: ALARCÓN ENZO | C11: WING | L11: =((IF(D11="SI",2,0)+(F11*5)+(G11*2)+(H11*2)-((IF(I11="SI",2,0)-((IF(J11="SI",-5,0)+((IF(K11="SI",10,0))))))))) -> 0 | N11: CONVERSIÓN | O11: 2
B12: ALCONADA AGUSTIN | C12: HOOKER | L12: =((IF(D12="SI",2,0)+(F12*5)+(G12*2)+(H12*2)-((IF(I12="SI",2,0)-((IF(J12="SI",-5,0)+((IF(K12="SI",10,0))))))))) -> 0 | N12: PENAL | O12: 3
B13: ALCONADA MARCOS | C13: CENTRO | L13: =((IF(D13="SI",2,0)+(F13*5)+(G13*2)+(H13*2)-((IF(I13="SI",2,0)-((IF(J13="SI",-5,0)+((IF(K13="SI",10,0))))))))) -> 0 | N13: TARJ. AMARILLA | O13: -3
B14: ALEGRE HOMERO | C14: MEDIOSCRUM | L14: =((IF(D14="SI",2,0)+(F14*5)+(G14*2)+(H14*2)-((IF(I14="SI",2,0)-((IF(J14="SI",-5,0)+((IF(K14="SI",10,0))))))))) -> 0 | N14: TARJ. ROJA | O14: -6
B15: ALMERARES GASPAR | C15: CENTRO | L15: =((IF(D15="SI",2,0)+(F15*5)+(G15*2)+(H15*2)-((IF(I15="SI",2,0)-((IF(J15="SI",-5,0)+((IF(K15="SI",10,0))))))))) -> 0 | N15: DEBUT | O15: 20
B16: ALONSO FELIPE | C16: MEDIOSCRUM | L16: =((IF(D16="SI",2,0)+(F16*5)+(G16*2)+(H16*2)-((IF(I16="SI",2,0)-((IF(J16="SI",-5,0)+((IF(K16="SI",10,0))))))))) -> 0
B17: ALONSO MATÍAS | C17: FULLBACK | L17: =((IF(D17="SI",2,0)+(F17*5)+(G17*2)+(H17*2)-((IF(I17="SI",2,0)-((IF(J17="SI",-5,0)+((IF(K17="SI",10,0))))))))) -> 0
B18: ALONSO TOMÁS | C18: SEGUNDA | L18: =((IF(D18="SI",2,0)+(F18*5)+(G18*2)+(H18*2)-((IF(I18="SI",2,0)-((IF(J18="SI",-5,0)+((IF(K18="SI",10,0))))))))) -> 0
B19: ALVAREZ HOGGAN RAMIRO | C19: PILAR | L19: =((IF(D19="SI",2,0)+(F19*5)+(G19*2)+(H19*2)-((IF(I19="SI",2,0)-((IF(J19="SI",-5,0)+((IF(K19="SI",10,0))))))))) -> 0
B20: ANNECHINI FELIPE | C20: CENTRO | L20: =((IF(D20="SI",2,0)+(F20*5)+(G20*2)+(H20*2)-((IF(I20="SI",2,0)-((IF(J20="SI",-5,0)+((IF(K20="SI",10,0))))))))) -> 0
B21: ANNECHINI FRANCISCO | C21: FULLBACK | L21: =((IF(D21="SI",2,0)+(F21*5)+(G21*2)+(H21*2)-((IF(I21="SI",2,0)-((IF(J21="SI",-5,0)+((IF(K21="SI",10,0))))))))) -> 0
B22: ANSELMINO FRANCISCO | C22: CENTRO | L22: =((IF(D22="SI",2,0)+(F22*5)+(G22*2)+(H22*2)-((IF(I22="SI",2,0)-((IF(J22="SI",-5,0)+((IF(K22="SI",10,0))))))))) -> 0
B23: ARAUJO DIEGO | C23: WING | L23: =((IF(D23="SI",2,0)+(F23*5)+(G23*2)+(H23*2)-((IF(I23="SI",2,0)-((IF(J23="SI",-5,0)+((IF(K23="SI",10,0))))))))) -> 0
B24: ARMISEN MATEO | C24: PILAR | L24: =((IF(D24="SI",2,0)+(F24*5)+(G24*2)+(H24*2)-((IF(I24="SI",2,0)-((IF(J24="SI",-5,0)+((IF(K24="SI",10,0))))))))) -> 0
B25: ARTECHE MANUEL | C25: WING | L25: =((IF(D25="SI",2,0)+(F25*5)+(G25*2)+(H25*2)-((IF(I25="SI",2,0)-((IF(J25="SI",-5,0)+((IF(K25="SI",10,0))))))))) -> 0
B26: ARTECHE TOMÁS | C26: WING | L26: =((IF(D26="SI",2,0)+(F26*5)+(G26*2)+(H26*2)-((IF(I26="SI",2,0)-((IF(J26="SI",-5,0)+((IF(K26="SI",10,0))))))))) -> 0
B27: BARBOZA TOMÁS | C27: SEGUNDA | L27: =((IF(D27="SI",2,0)+(F27*5)+(G27*2)+(H27*2)-((IF(I27="SI",2,0)-((IF(J27="SI",-5,0)+((IF(K27="SI",10,0))))))))) -> 0
... B74: CONTI FERMÍN | C74: PILAR | L74: =((IF(D74="SI",2,0)+(F74*5)+(G74*2)+(H74*2)-((IF(I74="SI",2,0)-((IF(J74="SI",-5,0)+((IF(K74="SI",10,0))))))))) -> 0
B75: CORONEL JERONIMO | L75: =((IF(D75="SI",2,0)+(F75*5)+(G75*2)+(H75*2)-((IF(I75="SI",2,0)-((IF(J75="SI",-5,0)+((IF(K75="SI",10,0))))))))) -> 0
B76: COSTE MANUEL | C76: TERCERA | L76: =((IF(D76="SI",2,0)+(F76*5)+(G76*2)+(H76*2)-((IF(I76="SI",2,0)-((IF(J76="SI",-5,0)+((IF(K76="SI",10,0))))))))) -> 0
B77: CRISPO JUAN IGNACIO | C77: CENTRO | L77: =((IF(D77="SI",2,0)+(F77*5)+(G77*2)+(H77*2)-((IF(I77="SI",2,0)-((IF(J77="SI",-5,0)+((IF(K77="SI",10,0))))))))) -> 0
B78: CUFRÉ AGUSTIN | C78: TERCERA | L78: =((IF(D78="SI",2,0)+(F78*5)+(G78*2)+(H78*2)-((IF(I78="SI",2,0)-((IF(J78="SI",-5,0)+((IF(K78="SI",10,0))))))))) -> 0
B79: CUNEO AGUSTIN | C79: TERCERA | L79: =((IF(D79="SI",2,0)+(F79*5)+(G79*2)+(H79*2)-((IF(I79="SI",2,0)-((IF(J79="SI",-5,0)+((IF(K79="SI",10,0))))))))) -> 0
B80: CUNHA BARAIBAR IÑAKI | C80: CENTRO | L80: =((IF(D80="SI",2,0)+(F80*5)+(G80*2)+(H80*2)-((IF(I80="SI",2,0)-((IF(J80="SI",-5,0)+((IF(K80="SI",10,0))))))))) -> 0
B81: CURUCHAGA JUAN CRUZ | C81: CENTRO | L81: =((IF(D81="SI",2,0)+(F81*5)+(G81*2)+(H81*2)-((IF(I81="SI",2,0)-((IF(J81="SI",-5,0)+((IF(K81="SI",10,0))))))))) -> 0
B82: CURUCHAGA SALVADOR | C82: TERCERA | L82: =((IF(D82="SI",2,0)+(F82*5)+(G82*2)+(H82*2)-((IF(I82="SI",2,0)-((IF(J82="SI",-5,0)+((IF(K82="SI",10,0))))))))) -> 0
B83: D ALESSANDRO FERMIN | C83: APERTURA | L83: =((IF(D83="SI",2,0)+(F83*5)+(G83*2)+(H83*2)-((IF(I83="SI",2,0)-((IF(J83="SI",-5,0)+((IF(K83="SI",10,0))))))))) -> 0
B84: DAGOSTINO FRANCISCO | C84: MEDIOSCRUM | L84: =((IF(D84="SI",2,0)+(F84*5)+(G84*2)+(H84*2)-((IF(I84="SI",2,0)-((IF(J84="SI",-5,0)+((IF(K84="SI",10,0))))))))) -> 0
B85: DARODA PEDRO | C85: TERCERA | L85: =((IF(D85="SI",2,0)+(F85*5)+(G85*2)+(H85*2)-((IF(I85="SI",2,0)-((IF(J85="SI",-5,0)+((IF(K85="SI",10,0))))))))) -> 0
B86: DE LA FUENTE MANUEL | C86: MEDIOSCRUM | L86: =((IF(D86="SI",2,0)+(F86*5)+(G86*2)+(H86*2)-((IF(I86="SI",2,0)-((IF(J86="SI",-5,0)+((IF(K86="SI",10,0))))))))) -> 0
B87: DE LAZZARI DINO | C87: WING | L87: =((IF(D87="SI",2,0)+(F87*5)+(G87*2)+(H87*2)-((IF(I87="SI",2,0)-((IF(J87="SI",-5,0)+((IF(K87="SI",10,0))))))))) -> 0
... B246: SAULNIER FRANCISCO | C246: MEDIOSCRUM | L246: =((IF(D246="SI",2,0)+(F246*5)+(G246*2)+(H246*2)-((IF(I246="SI",2,0)-((IF(J246="SI",-5,0)+((IF(K246="SI",10,0))))))))) -> 0

Sheet EVENTOS F5
B4: FECHA 5 | H4: vs BIEI | N4: JUGADOR CON MÁS PUNTOS DE LA FECHA | P4: =MAX(L7:L198) -> 0
B6: JUGADOR | C6: POSICIÓN | D6: TITULAR | E6: VICTORIA | F6: TRY | G6: CONVERSIÓN | H6: PENAL | I6: TARJ. AMAR | J6: TARJ. ROJA | K6: DEBUT | L6: PUNTAJE
B7: ABRIOLA JUAN | C7: TERCERA | L7: =((IF(D7="SI",2,0)+(F7*5)+(G7*2)+(H7*3)-((IF(I7="SI",3,0)-((IF(J7="SI",-6,0)+((IF(K7="SI",20,0)))+((IF(E7="SI",1,0))))))))) -> 0
B8: ADDIECHI FELIPE | C8: FULLBACK | L8: =((IF(D8="SI",2,0)+(F8*5)+(G8*2)+(H8*2)-((IF(I8="SI",2,0)-((IF(J8="SI",-5,0)+((IF(K8="SI",10,0))))))))) -> 0 | N8: TITULARIDAD | O8: =+2 -> 2
B9: ADDIECHI PEDRO | C9: WING | L9: =((IF(D9="SI",2,0)+(F9*5)+(G9*2)+(H9*2)-((IF(I9="SI",2,0)-((IF(J9="SI",-5,0)+((IF(K9="SI",10,0))))))))) -> 0 | N9: VICTORIA | O9: 1
B10: AKIMENKO TOMÁS | C10: PILAR | L10: =((IF(D10="SI",2,0)+(F10*5)+(G10*2)+(H10*2)-((IF(I10="SI",2,0)-((IF(J10="SI",-5,0)+((IF(K10="SI",10,0))))))))) -> 0 | N10: TRY | O10: 5
B11: ALARCÓN ENZO | C11: WING | L11: =((IF(D11="SI",2,0)+(F11*5)+(G11*2)+(H11*2)-((IF(I11="SI",2,0)-((IF(J11="SI",-5,0)+((IF(K11="SI",10,0))))))))) -> 0 | N11: CONVERSIÓN | O11: 2
B12: ALCONADA AGUSTIN | C12: HOOKER | L12: =((IF(D12="SI",2,0)+(F12*5)+(G12*2)+(H12*2)-((IF(I12="SI",2,0)-((IF(J12="SI",-5,0)+((IF(K12="SI",10,0))))))))) -> 0 | N12: PENAL | O12: 3
B13: ALCONADA MARCOS | C13: CENTRO | L13: =((IF(D13="SI",2,0)+(F13*5)+(G13*2)+(H13*2)-((IF(I13="SI",2,0)-((IF(J13="SI",-5,0)+((IF(K13="SI",10,0))))))))) -> 0 | N13: TARJ. AMARILLA | O13: -3
B14: ALEGRE HOMERO | C14: MEDIOSCRUM | L14: =((IF(D14="SI",2,0)+(F14*5)+(G14*2)+(H14*2)-((IF(I14="SI",2,0)-((IF(J14="SI",-5,0)+((IF(K14="SI",10,0))))))))) -> 0 | N14: TARJ. ROJA | O14: -6
B15: ALMERARES GASPAR | C15: CENTRO | L15: =((IF(D15="SI",2,0)+(F15*5)+(G15*2)+(H15*2)-((IF(I15="SI",2,0)-((IF(J15="SI",-5,0)+((IF(K15="SI",10,0))))))))) -> 0 | N15: DEBUT | O15: 20
B16: ALONSO FELIPE | C16: MEDIOSCRUM | L16: =((IF(D16="SI",2,0)+(F16*5)+(G16*2)+(H16*2)-((IF(I16="SI",2,0)-((IF(J16="SI",-5,0)+((IF(K16="SI",10,0))))))))) -> 0
B17: ALONSO MATÍAS | C17: FULLBACK | L17: =((IF(D17="SI",2,0)+(F17*5)+(G17*2)+(H17*2)-((IF(I17="SI",2,0)-((IF(J17="SI",-5,0)+((IF(K17="SI",10,0))))))))) -> 0
B18: ALONSO TOMÁS | C18: SEGUNDA | L18: =((IF(D18="SI",2,0)+(F18*5)+(G18*2)+(H18*2)-((IF(I18="SI",2,0)-((IF(J18="SI",-5,0)+((IF(K18="SI",10,0))))))))) -> 0
B19: ALVAREZ HOGGAN RAMIRO | C19: PILAR | L19: =((IF(D19="SI",2,0)+(F19*5)+(G19*2)+(H19*2)-((IF(I19="SI",2,0)-((IF(J19="SI",-5,0)+((IF(K19="SI",10,0))))))))) -> 0
B20: ANNECHINI FELIPE | C20: CENTRO | L20: =((IF(D20="SI",2,0)+(F20*5)+(G20*2)+(H20*2)-((IF(I20="SI",2,0)-((IF(J20="SI",-5,0)+((IF(K20="SI",10,0))))))))) -> 0
B21: ANNECHINI FRANCISCO | C21: FULLBACK | L21: =((IF(D21="SI",2,0)+(F21*5)+(G21*2)+(H21*2)-((IF(I21="SI",2,0)-((IF(J21="SI",-5,0)+((IF(K21="SI",10,0))))))))) -> 0
B22: ANSELMINO FRANCISCO | C22: CENTRO | L22: =((IF(D22="SI",2,0)+(F22*5)+(G22*2)+(H22*2)-((IF(I22="SI",2,0)-((IF(J22="SI",-5,0)+((IF(K22="SI",10,0))))))))) -> 0
B23: ARAUJO DIEGO | C23: WING | L23: =((IF(D23="SI",2,0)+(F23*5)+(G23*2)+(H23*2)-((IF(I23="SI",2,0)-((IF(J23="SI",-5,0)+((IF(K23="SI",10,0))))))))) -> 0
B24: ARMISEN MATEO | C24: PILAR | L24: =((IF(D24="SI",2,0)+(F24*5)+(G24*2)+(H24*2)-((IF(I24="SI",2,0)-((IF(J24="SI",-5,0)+((IF(K24="SI",10,0))))))))) -> 0
B25: ARTECHE MANUEL | C25: WING | L25: =((IF(D25="SI",2,0)+(F25*5)+(G25*2)+(H25*2)-((IF(I25="SI",2,0)-((IF(J25="SI",-5,0)+((IF(K25="SI",10,0))))))))) -> 0
B26: ARTECHE TOMÁS | C26: WING | L26: =((IF(D26="SI",2,0)+(F26*5)+(G26*2)+(H26*2)-((IF(I26="SI",2,0)-((IF(J26="SI",-5,0)+((IF(K26="SI",10,0))))))))) -> 0
B27: BARBOZA TOMÁS | C27: SEGUNDA | L27: =((IF(D27="SI",2,0)+(F27*5)+(G27*2)+(H27*2)-((IF(I27="SI",2,0)-((IF(J27="SI",-5,0)+((IF(K27="SI",10,0))))))))) -> 0
... B74: CONTI FERMÍN | C74: PILAR | L74: =((IF(D74="SI",2,0)+(F74*5)+(G74*2)+(H74*2)-((IF(I74="SI",2,0)-((IF(J74="SI",-5,0)+((IF(K74="SI",10,0))))))))) -> 0
B75: CORONEL JERONIMO | L75: =((IF(D75="SI",2,0)+(F75*5)+(G75*2)+(H75*2)-((IF(I75="SI",2,0)-((IF(J75="SI",-5,0)+((IF(K75="SI",10,0))))))))) -> 0
B76: COSTE MANUEL | C76: TERCERA | L76: =((IF(D76="SI",2,0)+(F76*5)+(G76*2)+(H76*2)-((IF(I76="SI",2,0)-((IF(J76="SI",-5,0)+((IF(K76="SI",10,0))))))))) -> 0
B77: CRISPO JUAN IGNACIO | C77: CENTRO | L77: =((IF(D77="SI",2,0)+(F77*5)+(G77*2)+(H77*2)-((IF(I77="SI",2,0)-((IF(J77="SI",-5,0)+((IF(K77="SI",10,0))))))))) -> 0
B78: CUFRÉ AGUSTIN | C78: TERCERA | L78: =((IF(D78="SI",2,0)+(F78*5)+(G78*2)+(H78*2)-((IF(I78="SI",2,0)-((IF(J78="SI",-5,0)+((IF(K78="SI",10,0))))))))) -> 0
B79: CUNEO AGUSTIN | C79: TERCERA | L79: =((IF(D79="SI",2,0)+(F79*5)+(G79*2)+(H79*2)-((IF(I79="SI",2,0)-((IF(J79="SI",-5,0)+((IF(K79="SI",10,0))))))))) -> 0
B80: CUNHA BARAIBAR IÑAKI | C80: CENTRO | L80: =((IF(D80="SI",2,0)+(F80*5)+(G80*2)+(H80*2)-((IF(I80="SI",2,0)-((IF(J80="SI",-5,0)+((IF(K80="SI",10,0))))))))) -> 0
B81: CURUCHAGA JUAN CRUZ | C81: CENTRO | L81: =((IF(D81="SI",2,0)+(F81*5)+(G81*2)+(H81*2)-((IF(I81="SI",2,0)-((IF(J81="SI",-5,0)+((IF(K81="SI",10,0))))))))) -> 0
B82: CURUCHAGA SALVADOR | C82: TERCERA | L82: =((IF(D82="SI",2,0)+(F82*5)+(G82*2)+(H82*2)-((IF(I82="SI",2,0)-((IF(J82="SI",-5,0)+((IF(K82="SI",10,0))))))))) -> 0
B83: D ALESSANDRO FERMIN | C83: APERTURA | L83: =((IF(D83="SI",2,0)+(F83*5)+(G83*2)+(H83*2)-((IF(I83="SI",2,0)-((IF(J83="SI",-5,0)+((IF(K83="SI",10,0))))))))) -> 0
B84: DAGOSTINO FRANCISCO | C84: MEDIOSCRUM | L84: =((IF(D84="SI",2,0)+(F84*5)+(G84*2)+(H84*2)-((IF(I84="SI",2,0)-((IF(J84="SI",-5,0)+((IF(K84="SI",10,0))))))))) -> 0
B85: DARODA PEDRO | C85: TERCERA | L85: =((IF(D85="SI",2,0)+(F85*5)+(G85*2)+(H85*2)-((IF(I85="SI",2,0)-((IF(J85="SI",-5,0)+((IF(K85="SI",10,0))))))))) -> 0
B86: DE LA FUENTE MANUEL | C86: MEDIOSCRUM | L86: =((IF(D86="SI",2,0)+(F86*5)+(G86*2)+(H86*2)-((IF(I86="SI",2,0)-((IF(J86="SI",-5,0)+((IF(K86="SI",10,0))))))))) -> 0
B87: DE LAZZARI DINO | C87: WING | L87: =((IF(D87="SI",2,0)+(F87*5)+(G87*2)+(H87*2)-((IF(I87="SI",2,0)-((IF(J87="SI",-5,0)+((IF(K87="SI",10,0))))))))) -> 0
... B246: SAULNIER FRANCISCO | C246: MEDIOSCRUM | L246: =((IF(D246="SI",2,0)+(F246*5)+(G246*2)+(H246*2)-((IF(I246="SI",2,0)-((IF(J246="SI",-5,0)+((IF(K246="SI",10,0))))))))) -> 0

Sheet EVENTOS F6
B4: FECHA 6 | H4: vs BELGRANO | N4: JUGADOR CON MÁS PUNTOS DE LA FECHA | P4: =MAX(L7:L198) -> 0
B6: JUGADOR | C6: POSICIÓN | D6: TITULAR | E6: VICTORIA | F6: TRY | G6: CONVERSIÓN | H6: PENAL | I6: TARJ. AMAR | J6: TARJ. ROJA | K6: DEBUT | L6: PUNTAJE
B7: ABRIOLA JUAN | C7: TERCERA | L7: =((IF(D7="SI",2,0)+(F7*5)+(G7*2)+(H7*3)-((IF(I7="SI",3,0)-((IF(J7="SI",-6,0)+((IF(K7="SI",20,0)))+((IF(E7="SI",1,0))))))))) -> 0
B8: ADDIECHI FELIPE | C8: FULLBACK | L8: =((IF(D8="SI",2,0)+(F8*5)+(G8*2)+(H8*2)-((IF(I8="SI",2,0)-((IF(J8="SI",-5,0)+((IF(K8="SI",10,0))))))))) -> 0 | N8: TITULARIDAD | O8: =+2 -> 2
B9: ADDIECHI PEDRO | C9: WING | L9: =((IF(D9="SI",2,0)+(F9*5)+(G9*2)+(H9*2)-((IF(I9="SI",2,0)-((IF(J9="SI",-5,0)+((IF(K9="SI",10,0))))))))) -> 0 | N9: VICTORIA | O9: 1
B10: AKIMENKO TOMÁS | C10: PILAR | L10: =((IF(D10="SI",2,0)+(F10*5)+(G10*2)+(H10*2)-((IF(I10="SI",2,0)-((IF(J10="SI",-5,0)+((IF(K10="SI",10,0))))))))) -> 0 | N10: TRY | O10: 5
B11: ALARCÓN ENZO | C11: WING | L11: =((IF(D11="SI",2,0)+(F11*5)+(G11*2)+(H11*2)-((IF(I11="SI",2,0)-((IF(J11="SI",-5,0)+((IF(K11="SI",10,0))))))))) -> 0 | N11: CONVERSIÓN | O11: 2
B12: ALCONADA AGUSTIN | C12: HOOKER | L12: =((IF(D12="SI",2,0)+(F12*5)+(G12*2)+(H12*2)-((IF(I12="SI",2,0)-((IF(J12="SI",-5,0)+((IF(K12="SI",10,0))))))))) -> 0 | N12: PENAL | O12: 3
B13: ALCONADA MARCOS | C13: CENTRO | L13: =((IF(D13="SI",2,0)+(F13*5)+(G13*2)+(H13*2)-((IF(I13="SI",2,0)-((IF(J13="SI",-5,0)+((IF(K13="SI",10,0))))))))) -> 0 | N13: TARJ. AMARILLA | O13: -3
B14: ALEGRE HOMERO | C14: MEDIOSCRUM | L14: =((IF(D14="SI",2,0)+(F14*5)+(G14*2)+(H14*2)-((IF(I14="SI",2,0)-((IF(J14="SI",-5,0)+((IF(K14="SI",10,0))))))))) -> 0 | N14: TARJ. ROJA | O14: -6
B15: ALMERARES GASPAR | C15: CENTRO | L15: =((IF(D15="SI",2,0)+(F15*5)+(G15*2)+(H15*2)-((IF(I15="SI",2,0)-((IF(J15="SI",-5,0)+((IF(K15="SI",10,0))))))))) -> 0 | N15: DEBUT | O15: 20
B16: ALONSO FELIPE | C16: MEDIOSCRUM | L16: =((IF(D16="SI",2,0)+(F16*5)+(G16*2)+(H16*2)-((IF(I16="SI",2,0)-((IF(J16="SI",-5,0)+((IF(K16="SI",10,0))))))))) -> 0
B17: ALONSO MATÍAS | C17: FULLBACK | L17: =((IF(D17="SI",2,0)+(F17*5)+(G17*2)+(H17*2)-((IF(I17="SI",2,0)-((IF(J17="SI",-5,0)+((IF(K17="SI",10,0))))))))) -> 0
B18: ALONSO TOMÁS | C18: SEGUNDA | L18: =((IF(D18="SI",2,0)+(F18*5)+(G18*2)+(H18*2)-((IF(I18="SI",2,0)-((IF(J18="SI",-5,0)+((IF(K18="SI",10,0))))))))) -> 0
B19: ALVAREZ HOGGAN RAMIRO | C19: PILAR | L19: =((IF(D19="SI",2,0)+(F19*5)+(G19*2)+(H19*2)-((IF(I19="SI",2,0)-((IF(J19="SI",-5,0)+((IF(K19="SI",10,0))))))))) -> 0
B20: ANNECHINI FELIPE | C20: CENTRO | L20: =((IF(D20="SI",2,0)+(F20*5)+(G20*2)+(H20*2)-((IF(I20="SI",2,0)-((IF(J20="SI",-5,0)+((IF(K20="SI",10,0))))))))) -> 0
B21: ANNECHINI FRANCISCO | C21: FULLBACK | L21: =((IF(D21="SI",2,0)+(F21*5)+(G21*2)+(H21*2)-((IF(I21="SI",2,0)-((IF(J21="SI",-5,0)+((IF(K21="SI",10,0))))))))) -> 0
B22: ANSELMINO FRANCISCO | C22: CENTRO | L22: =((IF(D22="SI",2,0)+(F22*5)+(G22*2)+(H22*2)-((IF(I22="SI",2,0)-((IF(J22="SI",-5,0)+((IF(K22="SI",10,0))))))))) -> 0
B23: ARAUJO DIEGO | C23: WING | L23: =((IF(D23="SI",2,0)+(F23*5)+(G23*2)+(H23*2)-((IF(I23="SI",2,0)-((IF(J23="SI",-5,0)+((IF(K23="SI",10,0))))))))) -> 0
B24: ARMISEN MATEO | C24: PILAR | L24: =((IF(D24="SI",2,0)+(F24*5)+(G24*2)+(H24*2)-((IF(I24="SI",2,0)-((IF(J24="SI",-5,0)+((IF(K24="SI",10,0))))))))) -> 0
B25: ARTECHE MANUEL | C25: WING | L25: =((IF(D25="SI",2,0)+(F25*5)+(G25*2)+(H25*2)-((IF(I25="SI",2,0)-((IF(J25="SI",-5,0)+((IF(K25="SI",10,0))))))))) -> 0
B26: ARTECHE TOMÁS | C26: WING | L26: =((IF(D26="SI",2,0)+(F26*5)+(G26*2)+(H26*2)-((IF(I26="SI",2,0)-((IF(J26="SI",-5,0)+((IF(K26="SI",10,0))))))))) -> 0
B27: BARBOZA TOMÁS | C27: SEGUNDA | L27: =((IF(D27="SI",2,0)+(F27*5)+(G27*2)+(H27*2)-((IF(I27="SI",2,0)-((IF(J27="SI",-5,0)+((IF(K27="SI",10,0))))))))) -> 0
... B74: CONTI FERMÍN | C74: PILAR | L74: =((IF(D74="SI",2,0)+(F74*5)+(G74*2)+(H74*2)-((IF(I74="SI",2,0)-((IF(J74="SI",-5,0)+((IF(K74="SI",10,0))))))))) -> 0
B75: CORONEL JERONIMO | L75: =((IF(D75="SI",2,0)+(F75*5)+(G75*2)+(H75*2)-((IF(I75="SI",2,0)-((IF(J75="SI",-5,0)+((IF(K75="SI",10,0))))))))) -> 0
B76: COSTE MANUEL | C76: TERCERA | L76: =((IF(D76="SI",2,0)+(F76*5)+(G76*2)+(H76*2)-((IF(I76="SI",2,0)-((IF(J76="SI",-5,0)+((IF(K76="SI",10,0))))))))) -> 0
B77: CRISPO JUAN IGNACIO | C77: CENTRO | L77: =((IF(D77="SI",2,0)+(F77*5)+(G77*2)+(H77*2)-((IF(I77="SI",2,0)-((IF(J77="SI",-5,0)+((IF(K77="SI",10,0))))))))) -> 0
B78: CUFRÉ AGUSTIN | C78: TERCERA | L78: =((IF(D78="SI",2,0)+(F78*5)+(G78*2)+(H78*2)-((IF(I78="SI",2,0)-((IF(J78="SI",-5,0)+((IF(K78="SI",10,0))))))))) -> 0
B79: CUNEO AGUSTIN | C79: TERCERA | L79: =((IF(D79="SI",2,0)+(F79*5)+(G79*2)+(H79*2)-((IF(I79="SI",2,0)-((IF(J79="SI",-5,0)+((IF(K79="SI",10,0))))))))) -> 0
B80: CUNHA BARAIBAR IÑAKI | C80: CENTRO | L80: =((IF(D80="SI",2,0)+(F80*5)+(G80*2)+(H80*2)-((IF(I80="SI",2,0)-((IF(J80="SI",-5,0)+((IF(K80="SI",10,0))))))))) -> 0
B81: CURUCHAGA JUAN CRUZ | C81: CENTRO | L81: =((IF(D81="SI",2,0)+(F81*5)+(G81*2)+(H81*2)-((IF(I81="SI",2,0)-((IF(J81="SI",-5,0)+((IF(K81="SI",10,0))))))))) -> 0
B82: CURUCHAGA SALVADOR | C82: TERCERA | L82: =((IF(D82="SI",2,0)+(F82*5)+(G82*2)+(H82*2)-((IF(I82="SI",2,0)-((IF(J82="SI",-5,0)+((IF(K82="SI",10,0))))))))) -> 0
B83: D ALESSANDRO FERMIN | C83: APERTURA | L83: =((IF(D83="SI",2,0)+(F83*5)+(G83*2)+(H83*2)-((IF(I83="SI",2,0)-((IF(J83="SI",-5,0)+((IF(K83="SI",10,0))))))))) -> 0
B84: DAGOSTINO FRANCISCO | C84: MEDIOSCRUM | L84: =((IF(D84="SI",2,0)+(F84*5)+(G84*2)+(H84*2)-((IF(I84="SI",2,0)-((IF(J84="SI",-5,0)+((IF(K84="SI",10,0))))))))) -> 0
B85: DARODA PEDRO | C85: TERCERA | L85: =((IF(D85="SI",2,0)+(F85*5)+(G85*2)+(H85*2)-((IF(I85="SI",2,0)-((IF(J85="SI",-5,0)+((IF(K85="SI",10,0))))))))) -> 0
B86: DE LA FUENTE MANUEL | C86: MEDIOSCRUM | L86: =((IF(D86="SI",2,0)+(F86*5)+(G86*2)+(H86*2)-((IF(I86="SI",2,0)-((IF(J86="SI",-5,0)+((IF(K86="SI",10,0))))))))) -> 0
B87: DE LAZZARI DINO | C87: WING | L87: =((IF(D87="SI",2,0)+(F87*5)+(G87*2)+(H87*2)-((IF(I87="SI",2,0)-((IF(J87="SI",-5,0)+((IF(K87="SI",10,0))))))))) -> 0
... B246: SAULNIER FRANCISCO | C246: MEDIOSCRUM | L246: =((IF(D246="SI",2,0)+(F246*5)+(G246*2)+(H246*2)-((IF(I246="SI",2,0)-((IF(J246="SI",-5,0)+((IF(K246="SI",10,0))))))))) -> 0

Sheet EVENTOS F7
B4: FECHA 7 | H4: vs SIC | N4: JUGADOR CON MÁS PUNTOS DE LA FECHA | P4: =MAX(L7:L198) -> 0
B6: JUGADOR | C6: POSICIÓN | D6: TITULAR | E6: VICTORIA | F6: TRY | G6: CONVERSIÓN | H6: PENAL | I6: TARJ. AMAR | J6: TARJ. ROJA | K6: DEBUT | L6: PUNTAJE
B7: ABRIOLA JUAN | C7: TERCERA | L7: =((IF(D7="SI",2,0)+(F7*5)+(G7*2)+(H7*3)-((IF(I7="SI",3,0)-((IF(J7="SI",-6,0)+((IF(K7="SI",20,0)))+((IF(E7="SI",1,0))))))))) -> 0
B8: ADDIECHI FELIPE | C8: FULLBACK | L8: =((IF(D8="SI",2,0)+(F8*5)+(G8*2)+(H8*2)-((IF(I8="SI",2,0)-((IF(J8="SI",-5,0)+((IF(K8="SI",10,0))))))))) -> 0 | N8: TITULARIDAD | O8: =+2 -> 2
B9: ADDIECHI PEDRO | C9: WING | L9: =((IF(D9="SI",2,0)+(F9*5)+(G9*2)+(H9*2)-((IF(I9="SI",2,0)-((IF(J9="SI",-5,0)+((IF(K9="SI",10,0))))))))) -> 0 | N9: VICTORIA | O9: 1
B10: AKIMENKO TOMÁS | C10: PILAR | L10: =((IF(D10="SI",2,0)+(F10*5)+(G10*2)+(H10*2)-((IF(I10="SI",2,0)-((IF(J10="SI",-5,0)+((IF(K10="SI",10,0))))))))) -> 0 | N10: TRY | O10: 5
